CommandError: "blancexchange" is not a valid port number or address:port pair.
CommandError: "blancexchange.net" is not a valid port number or address:port pair.
CommandError: "192.81.210.127" is not a valid port number or address:port pair.
CommandError: "192.81.210.127" is not a valid port number or address:port pair.
Performing system checks...

System check identified no issues (0 silenced).
June 15, 2024 - 11:25:47
Django version 4.2.11, using settings 'blankexchange.settings'
Starting development server at http://192.81.210.127:9000/
Quit the server with CONTROL-C.

Performing system checks...

System check identified no issues (0 silenced).
June 15, 2024 - 11:32:55
Django version 4.2.11, using settings 'blankexchange.settings'
Starting development server at http://192.81.210.127:9000/
Quit the server with CONTROL-C.

Performing system checks...

System check identified no issues (0 silenced).
June 15, 2024 - 11:34:10
Django version 4.2.11, using settings 'blankexchange.settings'
Starting development server at http://192.81.210.127:9000/
Quit the server with CONTROL-C.

Performing system checks...

System check identified no issues (0 silenced).
June 15, 2024 - 11:38:35
Django version 4.2.11, using settings 'blankexchange.settings'
Starting development server at http://192.81.210.127:9000/
Quit the server with CONTROL-C.

Performing system checks...

Exception in thread django-main-thread:
Traceback (most recent call last):
  File "/root/anaconda3/lib/python3.10/threading.py", line 1016, in _bootstrap_inner
    self.run()
  File "/root/anaconda3/lib/python3.10/threading.py", line 953, in run
    self._target(*self._args, **self._kwargs)
  File "/root/anaconda3/lib/python3.10/site-packages/django/utils/autoreload.py", line 64, in wrapper
    fn(*args, **kwargs)
  File "/root/anaconda3/lib/python3.10/site-packages/django/core/management/commands/runserver.py", line 133, in inner_run
    self.check(display_num_errors=True)
  File "/root/anaconda3/lib/python3.10/site-packages/django/core/management/base.py", line 485, in check
    all_issues = checks.run_checks(
  File "/root/anaconda3/lib/python3.10/site-packages/django/core/checks/registry.py", line 88, in run_checks
    new_errors = check(app_configs=app_configs, databases=databases)
  File "/root/anaconda3/lib/python3.10/site-packages/django/core/checks/urls.py", line 14, in check_url_config
    return check_resolver(resolver)
  File "/root/anaconda3/lib/python3.10/site-packages/django/core/checks/urls.py", line 24, in check_resolver
    return check_method()
  File "/root/anaconda3/lib/python3.10/site-packages/django/urls/resolvers.py", line 494, in check
    for pattern in self.url_patterns:
  File "/root/anaconda3/lib/python3.10/site-packages/django/utils/functional.py", line 57, in __get__
    res = instance.__dict__[self.name] = self.func(instance)
  File "/root/anaconda3/lib/python3.10/site-packages/django/urls/resolvers.py", line 715, in url_patterns
    patterns = getattr(self.urlconf_module, "urlpatterns", self.urlconf_module)
  File "/root/anaconda3/lib/python3.10/site-packages/django/utils/functional.py", line 57, in __get__
    res = instance.__dict__[self.name] = self.func(instance)
  File "/root/anaconda3/lib/python3.10/site-packages/django/urls/resolvers.py", line 708, in urlconf_module
    return import_module(self.urlconf_name)
  File "/root/anaconda3/lib/python3.10/importlib/__init__.py", line 126, in import_module
    return _bootstrap._gcd_import(name[level:], package, level)
  File "<frozen importlib._bootstrap>", line 1050, in _gcd_import
  File "<frozen importlib._bootstrap>", line 1027, in _find_and_load
  File "<frozen importlib._bootstrap>", line 1006, in _find_and_load_unlocked
  File "<frozen importlib._bootstrap>", line 688, in _load_unlocked
  File "<frozen importlib._bootstrap_external>", line 883, in exec_module
  File "<frozen importlib._bootstrap>", line 241, in _call_with_frames_removed
  File "/home/kc/blancexchangeapi/blankexchange/urls.py", line 44, in <module>
    path('',include(('core_app_root.security.auth.routers','core_app_root.security.auth'))),
  File "/root/anaconda3/lib/python3.10/site-packages/django/urls/conf.py", line 38, in include
    urlconf_module = import_module(urlconf_module)
  File "/root/anaconda3/lib/python3.10/importlib/__init__.py", line 126, in import_module
    return _bootstrap._gcd_import(name[level:], package, level)
  File "<frozen importlib._bootstrap>", line 1050, in _gcd_import
  File "<frozen importlib._bootstrap>", line 1027, in _find_and_load
  File "<frozen importlib._bootstrap>", line 1006, in _find_and_load_unlocked
  File "<frozen importlib._bootstrap>", line 688, in _load_unlocked
  File "<frozen importlib._bootstrap_external>", line 883, in exec_module
  File "<frozen importlib._bootstrap>", line 241, in _call_with_frames_removed
  File "/home/kc/blancexchangeapi/core_app_root/security/auth/routers.py", line 2, in <module>
    from core_app_root.security.auth.viewsets.register import RegisterViewSet
  File "/home/kc/blancexchangeapi/core_app_root/security/auth/viewsets/register.py", line 129
    receiver_email = email)
                          ^
SyntaxError: unmatched ')'
Performing system checks...

System check identified no issues (0 silenced).
June 15, 2024 - 11:38:58
Django version 4.2.11, using settings 'blankexchange.settings'
Starting development server at http://192.81.210.127:9000/
Quit the server with CONTROL-C.

Performing system checks...

System check identified no issues (0 silenced).
June 15, 2024 - 11:39:18
Django version 4.2.11, using settings 'blankexchange.settings'
Starting development server at http://192.81.210.127:9000/
Quit the server with CONTROL-C.

Performing system checks...

System check identified no issues (0 silenced).
June 15, 2024 - 11:40:39
Django version 4.2.11, using settings 'blankexchange.settings'
Starting development server at http://192.81.210.127:9000/
Quit the server with CONTROL-C.

Performing system checks...

Exception in thread django-main-thread:
Traceback (most recent call last):
  File "/root/anaconda3/lib/python3.10/threading.py", line 1016, in _bootstrap_inner
    self.run()
  File "/root/anaconda3/lib/python3.10/threading.py", line 953, in run
    self._target(*self._args, **self._kwargs)
  File "/root/anaconda3/lib/python3.10/site-packages/django/utils/autoreload.py", line 64, in wrapper
    fn(*args, **kwargs)
  File "/root/anaconda3/lib/python3.10/site-packages/django/core/management/commands/runserver.py", line 133, in inner_run
    self.check(display_num_errors=True)
  File "/root/anaconda3/lib/python3.10/site-packages/django/core/management/base.py", line 485, in check
    all_issues = checks.run_checks(
  File "/root/anaconda3/lib/python3.10/site-packages/django/core/checks/registry.py", line 88, in run_checks
    new_errors = check(app_configs=app_configs, databases=databases)
  File "/root/anaconda3/lib/python3.10/site-packages/django/core/checks/urls.py", line 14, in check_url_config
    return check_resolver(resolver)
  File "/root/anaconda3/lib/python3.10/site-packages/django/core/checks/urls.py", line 24, in check_resolver
    return check_method()
  File "/root/anaconda3/lib/python3.10/site-packages/django/urls/resolvers.py", line 494, in check
    for pattern in self.url_patterns:
  File "/root/anaconda3/lib/python3.10/site-packages/django/utils/functional.py", line 57, in __get__
    res = instance.__dict__[self.name] = self.func(instance)
  File "/root/anaconda3/lib/python3.10/site-packages/django/urls/resolvers.py", line 715, in url_patterns
    patterns = getattr(self.urlconf_module, "urlpatterns", self.urlconf_module)
  File "/root/anaconda3/lib/python3.10/site-packages/django/utils/functional.py", line 57, in __get__
    res = instance.__dict__[self.name] = self.func(instance)
  File "/root/anaconda3/lib/python3.10/site-packages/django/urls/resolvers.py", line 708, in urlconf_module
    return import_module(self.urlconf_name)
  File "/root/anaconda3/lib/python3.10/importlib/__init__.py", line 126, in import_module
    return _bootstrap._gcd_import(name[level:], package, level)
  File "<frozen importlib._bootstrap>", line 1050, in _gcd_import
  File "<frozen importlib._bootstrap>", line 1027, in _find_and_load
  File "<frozen importlib._bootstrap>", line 1006, in _find_and_load_unlocked
  File "<frozen importlib._bootstrap>", line 688, in _load_unlocked
  File "<frozen importlib._bootstrap_external>", line 883, in exec_module
  File "<frozen importlib._bootstrap>", line 241, in _call_with_frames_removed
  File "/home/kc/blancexchangeapi/blankexchange/urls.py", line 44, in <module>
    path('',include(('core_app_root.security.auth.routers','core_app_root.security.auth'))),
  File "/root/anaconda3/lib/python3.10/site-packages/django/urls/conf.py", line 38, in include
    urlconf_module = import_module(urlconf_module)
  File "/root/anaconda3/lib/python3.10/importlib/__init__.py", line 126, in import_module
    return _bootstrap._gcd_import(name[level:], package, level)
  File "<frozen importlib._bootstrap>", line 1050, in _gcd_import
  File "<frozen importlib._bootstrap>", line 1027, in _find_and_load
  File "<frozen importlib._bootstrap>", line 1006, in _find_and_load_unlocked
  File "<frozen importlib._bootstrap>", line 688, in _load_unlocked
  File "<frozen importlib._bootstrap_external>", line 883, in exec_module
  File "<frozen importlib._bootstrap>", line 241, in _call_with_frames_removed
  File "/home/kc/blancexchangeapi/core_app_root/security/auth/routers.py", line 2, in <module>
    from core_app_root.security.auth.viewsets.register import RegisterViewSet
  File "/home/kc/blancexchangeapi/core_app_root/security/auth/viewsets/register.py", line 131
    body = f"Enter the four digit code sent to you here in your Blanc Exchange application to continue with account registration completion   {{activation_code} , you can copy and paste the activation code"
                                                                                                                                                                                                              ^
SyntaxError: f-string: single '}' is not allowed
Performing system checks...

System check identified no issues (0 silenced).
June 15, 2024 - 11:44:44
Django version 4.2.11, using settings 'blankexchange.settings'
Starting development server at http://192.81.210.127:9000/
Quit the server with CONTROL-C.

Performing system checks...

System check identified no issues (0 silenced).
June 15, 2024 - 11:45:06
Django version 4.2.11, using settings 'blankexchange.settings'
Starting development server at http://192.81.210.127:9000/
Quit the server with CONTROL-C.

Performing system checks...

System check identified no issues (0 silenced).
June 15, 2024 - 11:51:56
Django version 4.2.11, using settings 'blankexchange.settings'
Starting development server at http://192.81.210.127:9000/
Quit the server with CONTROL-C.

Performing system checks...

System check identified no issues (0 silenced).
June 15, 2024 - 11:52:49
Django version 4.2.11, using settings 'blankexchange.settings'
Starting development server at http://192.81.210.127:9000/
Quit the server with CONTROL-C.

Performing system checks...

System check identified no issues (0 silenced).
June 15, 2024 - 14:43:45
Django version 4.2.11, using settings 'blankexchange.settings'
Starting development server at http://192.81.210.127:9000/
Quit the server with CONTROL-C.

Performing system checks...

System check identified no issues (0 silenced).
June 15, 2024 - 14:46:04
Django version 4.2.11, using settings 'blankexchange.settings'
Starting development server at http://192.81.210.127:9000/
Quit the server with CONTROL-C.

Performing system checks...

System check identified no issues (0 silenced).
June 15, 2024 - 14:46:08
Django version 4.2.11, using settings 'blankexchange.settings'
Starting development server at http://192.81.210.127:9000/
Quit the server with CONTROL-C.

Performing system checks...

System check identified no issues (0 silenced).
June 15, 2024 - 14:54:05
Django version 4.2.11, using settings 'blankexchange.settings'
Starting development server at http://192.81.210.127:9000/
Quit the server with CONTROL-C.

Performing system checks...

System check identified no issues (0 silenced).
June 15, 2024 - 14:54:21
Django version 4.2.11, using settings 'blankexchange.settings'
Starting development server at http://192.81.210.127:9000/
Quit the server with CONTROL-C.

Performing system checks...

System check identified no issues (0 silenced).
June 15, 2024 - 14:55:27
Django version 4.2.11, using settings 'blankexchange.settings'
Starting development server at http://192.81.210.127:9000/
Quit the server with CONTROL-C.

Performing system checks...

System check identified no issues (0 silenced).
June 15, 2024 - 14:55:30
Django version 4.2.11, using settings 'blankexchange.settings'
Starting development server at http://192.81.210.127:9000/
Quit the server with CONTROL-C.

Performing system checks...

System check identified no issues (0 silenced).
June 15, 2024 - 14:55:34
Django version 4.2.11, using settings 'blankexchange.settings'
Starting development server at http://192.81.210.127:9000/
Quit the server with CONTROL-C.

Performing system checks...

System check identified no issues (0 silenced).
June 15, 2024 - 14:55:37
Django version 4.2.11, using settings 'blankexchange.settings'
Starting development server at http://192.81.210.127:9000/
Quit the server with CONTROL-C.

Performing system checks...

System check identified no issues (0 silenced).
June 15, 2024 - 14:55:56
Django version 4.2.11, using settings 'blankexchange.settings'
Starting development server at http://192.81.210.127:9000/
Quit the server with CONTROL-C.

Performing system checks...

System check identified no issues (0 silenced).
June 15, 2024 - 14:57:01
Django version 4.2.11, using settings 'blankexchange.settings'
Starting development server at http://192.81.210.127:9000/
Quit the server with CONTROL-C.

Performing system checks...

System check identified no issues (0 silenced).
June 15, 2024 - 14:58:15
Django version 4.2.11, using settings 'blankexchange.settings'
Starting development server at http://192.81.210.127:9000/
Quit the server with CONTROL-C.

Performing system checks...

System check identified no issues (0 silenced).
June 15, 2024 - 14:58:30
Django version 4.2.11, using settings 'blankexchange.settings'
Starting development server at http://192.81.210.127:9000/
Quit the server with CONTROL-C.

Performing system checks...

System check identified no issues (0 silenced).
June 15, 2024 - 14:58:40
Django version 4.2.11, using settings 'blankexchange.settings'
Starting development server at http://192.81.210.127:9000/
Quit the server with CONTROL-C.

Performing system checks...

Exception in thread django-main-thread:
Traceback (most recent call last):
  File "/root/anaconda3/lib/python3.10/threading.py", line 1016, in _bootstrap_inner
    self.run()
  File "/root/anaconda3/lib/python3.10/threading.py", line 953, in run
    self._target(*self._args, **self._kwargs)
  File "/root/anaconda3/lib/python3.10/site-packages/django/utils/autoreload.py", line 64, in wrapper
    fn(*args, **kwargs)
  File "/root/anaconda3/lib/python3.10/site-packages/django/core/management/commands/runserver.py", line 133, in inner_run
    self.check(display_num_errors=True)
  File "/root/anaconda3/lib/python3.10/site-packages/django/core/management/base.py", line 485, in check
    all_issues = checks.run_checks(
  File "/root/anaconda3/lib/python3.10/site-packages/django/core/checks/registry.py", line 88, in run_checks
    new_errors = check(app_configs=app_configs, databases=databases)
  File "/root/anaconda3/lib/python3.10/site-packages/django/core/checks/urls.py", line 14, in check_url_config
    return check_resolver(resolver)
  File "/root/anaconda3/lib/python3.10/site-packages/django/core/checks/urls.py", line 24, in check_resolver
    return check_method()
  File "/root/anaconda3/lib/python3.10/site-packages/django/urls/resolvers.py", line 494, in check
    for pattern in self.url_patterns:
  File "/root/anaconda3/lib/python3.10/site-packages/django/utils/functional.py", line 57, in __get__
    res = instance.__dict__[self.name] = self.func(instance)
  File "/root/anaconda3/lib/python3.10/site-packages/django/urls/resolvers.py", line 715, in url_patterns
    patterns = getattr(self.urlconf_module, "urlpatterns", self.urlconf_module)
  File "/root/anaconda3/lib/python3.10/site-packages/django/utils/functional.py", line 57, in __get__
    res = instance.__dict__[self.name] = self.func(instance)
  File "/root/anaconda3/lib/python3.10/site-packages/django/urls/resolvers.py", line 708, in urlconf_module
    return import_module(self.urlconf_name)
  File "/root/anaconda3/lib/python3.10/importlib/__init__.py", line 126, in import_module
    return _bootstrap._gcd_import(name[level:], package, level)
  File "<frozen importlib._bootstrap>", line 1050, in _gcd_import
  File "<frozen importlib._bootstrap>", line 1027, in _find_and_load
  File "<frozen importlib._bootstrap>", line 1006, in _find_and_load_unlocked
  File "<frozen importlib._bootstrap>", line 688, in _load_unlocked
  File "<frozen importlib._bootstrap_external>", line 883, in exec_module
  File "<frozen importlib._bootstrap>", line 241, in _call_with_frames_removed
  File "/home/kc/blancexchangeapi/blankexchange/urls.py", line 44, in <module>
    path('',include(('core_app_root.security.auth.routers','core_app_root.security.auth'))),
  File "/root/anaconda3/lib/python3.10/site-packages/django/urls/conf.py", line 38, in include
    urlconf_module = import_module(urlconf_module)
  File "/root/anaconda3/lib/python3.10/importlib/__init__.py", line 126, in import_module
    return _bootstrap._gcd_import(name[level:], package, level)
  File "<frozen importlib._bootstrap>", line 1050, in _gcd_import
  File "<frozen importlib._bootstrap>", line 1027, in _find_and_load
  File "<frozen importlib._bootstrap>", line 1006, in _find_and_load_unlocked
  File "<frozen importlib._bootstrap>", line 688, in _load_unlocked
  File "<frozen importlib._bootstrap_external>", line 883, in exec_module
  File "<frozen importlib._bootstrap>", line 241, in _call_with_frames_removed
  File "/home/kc/blancexchangeapi/core_app_root/security/auth/routers.py", line 2, in <module>
    from core_app_root.security.auth.viewsets.register import RegisterViewSet
  File "/home/kc/blancexchangeapi/core_app_root/security/auth/viewsets/register.py", line 172
    await self.sen
    ^^^^^^^^^^^^^^
SyntaxError: 'await' outside async function
Performing system checks...

Exception in thread django-main-thread:
Traceback (most recent call last):
  File "/root/anaconda3/lib/python3.10/threading.py", line 1016, in _bootstrap_inner
    self.run()
  File "/root/anaconda3/lib/python3.10/threading.py", line 953, in run
    self._target(*self._args, **self._kwargs)
  File "/root/anaconda3/lib/python3.10/site-packages/django/utils/autoreload.py", line 64, in wrapper
    fn(*args, **kwargs)
  File "/root/anaconda3/lib/python3.10/site-packages/django/core/management/commands/runserver.py", line 133, in inner_run
    self.check(display_num_errors=True)
  File "/root/anaconda3/lib/python3.10/site-packages/django/core/management/base.py", line 485, in check
    all_issues = checks.run_checks(
  File "/root/anaconda3/lib/python3.10/site-packages/django/core/checks/registry.py", line 88, in run_checks
    new_errors = check(app_configs=app_configs, databases=databases)
  File "/root/anaconda3/lib/python3.10/site-packages/django/core/checks/urls.py", line 14, in check_url_config
    return check_resolver(resolver)
  File "/root/anaconda3/lib/python3.10/site-packages/django/core/checks/urls.py", line 24, in check_resolver
    return check_method()
  File "/root/anaconda3/lib/python3.10/site-packages/django/urls/resolvers.py", line 494, in check
    for pattern in self.url_patterns:
  File "/root/anaconda3/lib/python3.10/site-packages/django/utils/functional.py", line 57, in __get__
    res = instance.__dict__[self.name] = self.func(instance)
  File "/root/anaconda3/lib/python3.10/site-packages/django/urls/resolvers.py", line 715, in url_patterns
    patterns = getattr(self.urlconf_module, "urlpatterns", self.urlconf_module)
  File "/root/anaconda3/lib/python3.10/site-packages/django/utils/functional.py", line 57, in __get__
    res = instance.__dict__[self.name] = self.func(instance)
  File "/root/anaconda3/lib/python3.10/site-packages/django/urls/resolvers.py", line 708, in urlconf_module
    return import_module(self.urlconf_name)
  File "/root/anaconda3/lib/python3.10/importlib/__init__.py", line 126, in import_module
    return _bootstrap._gcd_import(name[level:], package, level)
  File "<frozen importlib._bootstrap>", line 1050, in _gcd_import
  File "<frozen importlib._bootstrap>", line 1027, in _find_and_load
  File "<frozen importlib._bootstrap>", line 1006, in _find_and_load_unlocked
  File "<frozen importlib._bootstrap>", line 688, in _load_unlocked
  File "<frozen importlib._bootstrap_external>", line 883, in exec_module
  File "<frozen importlib._bootstrap>", line 241, in _call_with_frames_removed
  File "/home/kc/blancexchangeapi/blankexchange/urls.py", line 44, in <module>
    path('',include(('core_app_root.security.auth.routers','core_app_root.security.auth'))),
  File "/root/anaconda3/lib/python3.10/site-packages/django/urls/conf.py", line 38, in include
    urlconf_module = import_module(urlconf_module)
  File "/root/anaconda3/lib/python3.10/importlib/__init__.py", line 126, in import_module
    return _bootstrap._gcd_import(name[level:], package, level)
  File "<frozen importlib._bootstrap>", line 1050, in _gcd_import
  File "<frozen importlib._bootstrap>", line 1027, in _find_and_load
  File "<frozen importlib._bootstrap>", line 1006, in _find_and_load_unlocked
  File "<frozen importlib._bootstrap>", line 688, in _load_unlocked
  File "<frozen importlib._bootstrap_external>", line 883, in exec_module
  File "<frozen importlib._bootstrap>", line 241, in _call_with_frames_removed
  File "/home/kc/blancexchangeapi/core_app_root/security/auth/routers.py", line 2, in <module>
    from core_app_root.security.auth.viewsets.register import RegisterViewSet
  File "/home/kc/blancexchangeapi/core_app_root/security/auth/viewsets/register.py", line 172
    await self.
               ^
SyntaxError: invalid syntax
Performing system checks...

Exception in thread django-main-thread:
Traceback (most recent call last):
  File "/root/anaconda3/lib/python3.10/threading.py", line 1016, in _bootstrap_inner
    self.run()
  File "/root/anaconda3/lib/python3.10/threading.py", line 953, in run
    self._target(*self._args, **self._kwargs)
  File "/root/anaconda3/lib/python3.10/site-packages/django/utils/autoreload.py", line 64, in wrapper
    fn(*args, **kwargs)
  File "/root/anaconda3/lib/python3.10/site-packages/django/core/management/commands/runserver.py", line 133, in inner_run
    self.check(display_num_errors=True)
  File "/root/anaconda3/lib/python3.10/site-packages/django/core/management/base.py", line 485, in check
    all_issues = checks.run_checks(
  File "/root/anaconda3/lib/python3.10/site-packages/django/core/checks/registry.py", line 88, in run_checks
    new_errors = check(app_configs=app_configs, databases=databases)
  File "/root/anaconda3/lib/python3.10/site-packages/django/core/checks/urls.py", line 14, in check_url_config
    return check_resolver(resolver)
  File "/root/anaconda3/lib/python3.10/site-packages/django/core/checks/urls.py", line 24, in check_resolver
    return check_method()
  File "/root/anaconda3/lib/python3.10/site-packages/django/urls/resolvers.py", line 494, in check
    for pattern in self.url_patterns:
  File "/root/anaconda3/lib/python3.10/site-packages/django/utils/functional.py", line 57, in __get__
    res = instance.__dict__[self.name] = self.func(instance)
  File "/root/anaconda3/lib/python3.10/site-packages/django/urls/resolvers.py", line 715, in url_patterns
    patterns = getattr(self.urlconf_module, "urlpatterns", self.urlconf_module)
  File "/root/anaconda3/lib/python3.10/site-packages/django/utils/functional.py", line 57, in __get__
    res = instance.__dict__[self.name] = self.func(instance)
  File "/root/anaconda3/lib/python3.10/site-packages/django/urls/resolvers.py", line 708, in urlconf_module
    return import_module(self.urlconf_name)
  File "/root/anaconda3/lib/python3.10/importlib/__init__.py", line 126, in import_module
    return _bootstrap._gcd_import(name[level:], package, level)
  File "<frozen importlib._bootstrap>", line 1050, in _gcd_import
  File "<frozen importlib._bootstrap>", line 1027, in _find_and_load
  File "<frozen importlib._bootstrap>", line 1006, in _find_and_load_unlocked
  File "<frozen importlib._bootstrap>", line 688, in _load_unlocked
  File "<frozen importlib._bootstrap_external>", line 883, in exec_module
  File "<frozen importlib._bootstrap>", line 241, in _call_with_frames_removed
  File "/home/kc/blancexchangeapi/blankexchange/urls.py", line 44, in <module>
    path('',include(('core_app_root.security.auth.routers','core_app_root.security.auth'))),
  File "/root/anaconda3/lib/python3.10/site-packages/django/urls/conf.py", line 38, in include
    urlconf_module = import_module(urlconf_module)
  File "/root/anaconda3/lib/python3.10/importlib/__init__.py", line 126, in import_module
    return _bootstrap._gcd_import(name[level:], package, level)
  File "<frozen importlib._bootstrap>", line 1050, in _gcd_import
  File "<frozen importlib._bootstrap>", line 1027, in _find_and_load
  File "<frozen importlib._bootstrap>", line 1006, in _find_and_load_unlocked
  File "<frozen importlib._bootstrap>", line 688, in _load_unlocked
  File "<frozen importlib._bootstrap_external>", line 883, in exec_module
  File "<frozen importlib._bootstrap>", line 241, in _call_with_frames_removed
  File "/home/kc/blancexchangeapi/core_app_root/security/auth/routers.py", line 2, in <module>
    from core_app_root.security.auth.viewsets.register import RegisterViewSet
  File "/home/kc/blancexchangeapi/core_app_root/security/auth/viewsets/register.py", line 172
    await self.send_
    ^^^^^^^^^^^^^^^^
SyntaxError: 'await' outside async function
Performing system checks...

System check identified no issues (0 silenced).
June 15, 2024 - 14:59:33
Django version 4.2.11, using settings 'blankexchange.settings'
Starting development server at http://192.81.210.127:9000/
Quit the server with CONTROL-C.

Performing system checks...

System check identified no issues (0 silenced).
June 15, 2024 - 14:59:49
Django version 4.2.11, using settings 'blankexchange.settings'
Starting development server at http://192.81.210.127:9000/
Quit the server with CONTROL-C.

Performing system checks...

Exception in thread django-main-thread:
Traceback (most recent call last):
  File "/root/anaconda3/lib/python3.10/threading.py", line 1016, in _bootstrap_inner
    self.run()
  File "/root/anaconda3/lib/python3.10/threading.py", line 953, in run
    self._target(*self._args, **self._kwargs)
  File "/root/anaconda3/lib/python3.10/site-packages/django/utils/autoreload.py", line 64, in wrapper
    fn(*args, **kwargs)
  File "/root/anaconda3/lib/python3.10/site-packages/django/core/management/commands/runserver.py", line 133, in inner_run
    self.check(display_num_errors=True)
  File "/root/anaconda3/lib/python3.10/site-packages/django/core/management/base.py", line 485, in check
    all_issues = checks.run_checks(
  File "/root/anaconda3/lib/python3.10/site-packages/django/core/checks/registry.py", line 88, in run_checks
    new_errors = check(app_configs=app_configs, databases=databases)
  File "/root/anaconda3/lib/python3.10/site-packages/django/core/checks/urls.py", line 14, in check_url_config
    return check_resolver(resolver)
  File "/root/anaconda3/lib/python3.10/site-packages/django/core/checks/urls.py", line 24, in check_resolver
    return check_method()
  File "/root/anaconda3/lib/python3.10/site-packages/django/urls/resolvers.py", line 494, in check
    for pattern in self.url_patterns:
  File "/root/anaconda3/lib/python3.10/site-packages/django/utils/functional.py", line 57, in __get__
    res = instance.__dict__[self.name] = self.func(instance)
  File "/root/anaconda3/lib/python3.10/site-packages/django/urls/resolvers.py", line 715, in url_patterns
    patterns = getattr(self.urlconf_module, "urlpatterns", self.urlconf_module)
  File "/root/anaconda3/lib/python3.10/site-packages/django/utils/functional.py", line 57, in __get__
    res = instance.__dict__[self.name] = self.func(instance)
  File "/root/anaconda3/lib/python3.10/site-packages/django/urls/resolvers.py", line 708, in urlconf_module
    return import_module(self.urlconf_name)
  File "/root/anaconda3/lib/python3.10/importlib/__init__.py", line 126, in import_module
    return _bootstrap._gcd_import(name[level:], package, level)
  File "<frozen importlib._bootstrap>", line 1050, in _gcd_import
  File "<frozen importlib._bootstrap>", line 1027, in _find_and_load
  File "<frozen importlib._bootstrap>", line 1006, in _find_and_load_unlocked
  File "<frozen importlib._bootstrap>", line 688, in _load_unlocked
  File "<frozen importlib._bootstrap_external>", line 883, in exec_module
  File "<frozen importlib._bootstrap>", line 241, in _call_with_frames_removed
  File "/home/kc/blancexchangeapi/blankexchange/urls.py", line 44, in <module>
    path('',include(('core_app_root.security.auth.routers','core_app_root.security.auth'))),
  File "/root/anaconda3/lib/python3.10/site-packages/django/urls/conf.py", line 38, in include
    urlconf_module = import_module(urlconf_module)
  File "/root/anaconda3/lib/python3.10/importlib/__init__.py", line 126, in import_module
    return _bootstrap._gcd_import(name[level:], package, level)
  File "<frozen importlib._bootstrap>", line 1050, in _gcd_import
  File "<frozen importlib._bootstrap>", line 1027, in _find_and_load
  File "<frozen importlib._bootstrap>", line 1006, in _find_and_load_unlocked
  File "<frozen importlib._bootstrap>", line 688, in _load_unlocked
  File "<frozen importlib._bootstrap_external>", line 883, in exec_module
  File "<frozen importlib._bootstrap>", line 241, in _call_with_frames_removed
  File "/home/kc/blancexchangeapi/core_app_root/security/auth/routers.py", line 2, in <module>
    from core_app_root.security.auth.viewsets.register import RegisterViewSet
  File "/home/kc/blancexchangeapi/core_app_root/security/auth/viewsets/register.py", line 32
    import asyncio
IndentationError: unexpected indent
Performing system checks...

Exception in thread django-main-thread:
Traceback (most recent call last):
  File "/root/anaconda3/lib/python3.10/threading.py", line 1016, in _bootstrap_inner
    self.run()
  File "/root/anaconda3/lib/python3.10/threading.py", line 953, in run
    self._target(*self._args, **self._kwargs)
  File "/root/anaconda3/lib/python3.10/site-packages/django/utils/autoreload.py", line 64, in wrapper
    fn(*args, **kwargs)
  File "/root/anaconda3/lib/python3.10/site-packages/django/core/management/commands/runserver.py", line 133, in inner_run
    self.check(display_num_errors=True)
  File "/root/anaconda3/lib/python3.10/site-packages/django/core/management/base.py", line 485, in check
    all_issues = checks.run_checks(
  File "/root/anaconda3/lib/python3.10/site-packages/django/core/checks/registry.py", line 88, in run_checks
    new_errors = check(app_configs=app_configs, databases=databases)
  File "/root/anaconda3/lib/python3.10/site-packages/django/core/checks/urls.py", line 14, in check_url_config
    return check_resolver(resolver)
  File "/root/anaconda3/lib/python3.10/site-packages/django/core/checks/urls.py", line 24, in check_resolver
    return check_method()
  File "/root/anaconda3/lib/python3.10/site-packages/django/urls/resolvers.py", line 494, in check
    for pattern in self.url_patterns:
  File "/root/anaconda3/lib/python3.10/site-packages/django/utils/functional.py", line 57, in __get__
    res = instance.__dict__[self.name] = self.func(instance)
  File "/root/anaconda3/lib/python3.10/site-packages/django/urls/resolvers.py", line 715, in url_patterns
    patterns = getattr(self.urlconf_module, "urlpatterns", self.urlconf_module)
  File "/root/anaconda3/lib/python3.10/site-packages/django/utils/functional.py", line 57, in __get__
    res = instance.__dict__[self.name] = self.func(instance)
  File "/root/anaconda3/lib/python3.10/site-packages/django/urls/resolvers.py", line 708, in urlconf_module
    return import_module(self.urlconf_name)
  File "/root/anaconda3/lib/python3.10/importlib/__init__.py", line 126, in import_module
    return _bootstrap._gcd_import(name[level:], package, level)
  File "<frozen importlib._bootstrap>", line 1050, in _gcd_import
  File "<frozen importlib._bootstrap>", line 1027, in _find_and_load
  File "<frozen importlib._bootstrap>", line 1006, in _find_and_load_unlocked
  File "<frozen importlib._bootstrap>", line 688, in _load_unlocked
  File "<frozen importlib._bootstrap_external>", line 883, in exec_module
  File "<frozen importlib._bootstrap>", line 241, in _call_with_frames_removed
  File "/home/kc/blancexchangeapi/blankexchange/urls.py", line 44, in <module>
    path('',include(('core_app_root.security.auth.routers','core_app_root.security.auth'))),
  File "/root/anaconda3/lib/python3.10/site-packages/django/urls/conf.py", line 38, in include
    urlconf_module = import_module(urlconf_module)
  File "/root/anaconda3/lib/python3.10/importlib/__init__.py", line 126, in import_module
    return _bootstrap._gcd_import(name[level:], package, level)
  File "<frozen importlib._bootstrap>", line 1050, in _gcd_import
  File "<frozen importlib._bootstrap>", line 1027, in _find_and_load
  File "<frozen importlib._bootstrap>", line 1006, in _find_and_load_unlocked
  File "<frozen importlib._bootstrap>", line 688, in _load_unlocked
  File "<frozen importlib._bootstrap_external>", line 883, in exec_module
  File "<frozen importlib._bootstrap>", line 241, in _call_with_frames_removed
  File "/home/kc/blancexchangeapi/core_app_root/security/auth/routers.py", line 2, in <module>
    from core_app_root.security.auth.viewsets.register import RegisterViewSet
  File "/home/kc/blancexchangeapi/core_app_root/security/auth/viewsets/register.py", line 32
    import asyncio
IndentationError: unexpected indent
Performing system checks...

System check identified no issues (0 silenced).
June 15, 2024 - 15:00:05
Django version 4.2.11, using settings 'blankexchange.settings'
Starting development server at http://192.81.210.127:9000/
Quit the server with CONTROL-C.

Performing system checks...

System check identified no issues (0 silenced).
June 15, 2024 - 15:00:42
Django version 4.2.11, using settings 'blankexchange.settings'
Starting development server at http://192.81.210.127:9000/
Quit the server with CONTROL-C.

Performing system checks...

System check identified no issues (0 silenced).
June 15, 2024 - 15:00:46
Django version 4.2.11, using settings 'blankexchange.settings'
Starting development server at http://192.81.210.127:9000/
Quit the server with CONTROL-C.

Performing system checks...

Exception in thread django-main-thread:
Traceback (most recent call last):
  File "/root/anaconda3/lib/python3.10/threading.py", line 1016, in _bootstrap_inner
    self.run()
  File "/root/anaconda3/lib/python3.10/threading.py", line 953, in run
    self._target(*self._args, **self._kwargs)
  File "/root/anaconda3/lib/python3.10/site-packages/django/utils/autoreload.py", line 64, in wrapper
    fn(*args, **kwargs)
  File "/root/anaconda3/lib/python3.10/site-packages/django/core/management/commands/runserver.py", line 133, in inner_run
    self.check(display_num_errors=True)
  File "/root/anaconda3/lib/python3.10/site-packages/django/core/management/base.py", line 485, in check
    all_issues = checks.run_checks(
  File "/root/anaconda3/lib/python3.10/site-packages/django/core/checks/registry.py", line 88, in run_checks
    new_errors = check(app_configs=app_configs, databases=databases)
  File "/root/anaconda3/lib/python3.10/site-packages/django/core/checks/urls.py", line 14, in check_url_config
    return check_resolver(resolver)
  File "/root/anaconda3/lib/python3.10/site-packages/django/core/checks/urls.py", line 24, in check_resolver
    return check_method()
  File "/root/anaconda3/lib/python3.10/site-packages/django/urls/resolvers.py", line 494, in check
    for pattern in self.url_patterns:
  File "/root/anaconda3/lib/python3.10/site-packages/django/utils/functional.py", line 57, in __get__
    res = instance.__dict__[self.name] = self.func(instance)
  File "/root/anaconda3/lib/python3.10/site-packages/django/urls/resolvers.py", line 715, in url_patterns
    patterns = getattr(self.urlconf_module, "urlpatterns", self.urlconf_module)
  File "/root/anaconda3/lib/python3.10/site-packages/django/utils/functional.py", line 57, in __get__
    res = instance.__dict__[self.name] = self.func(instance)
  File "/root/anaconda3/lib/python3.10/site-packages/django/urls/resolvers.py", line 708, in urlconf_module
    return import_module(self.urlconf_name)
  File "/root/anaconda3/lib/python3.10/importlib/__init__.py", line 126, in import_module
    return _bootstrap._gcd_import(name[level:], package, level)
  File "<frozen importlib._bootstrap>", line 1050, in _gcd_import
  File "<frozen importlib._bootstrap>", line 1027, in _find_and_load
  File "<frozen importlib._bootstrap>", line 1006, in _find_and_load_unlocked
  File "<frozen importlib._bootstrap>", line 688, in _load_unlocked
  File "<frozen importlib._bootstrap_external>", line 883, in exec_module
  File "<frozen importlib._bootstrap>", line 241, in _call_with_frames_removed
  File "/home/kc/blancexchangeapi/blankexchange/urls.py", line 44, in <module>
    path('',include(('core_app_root.security.auth.routers','core_app_root.security.auth'))),
  File "/root/anaconda3/lib/python3.10/site-packages/django/urls/conf.py", line 38, in include
    urlconf_module = import_module(urlconf_module)
  File "/root/anaconda3/lib/python3.10/importlib/__init__.py", line 126, in import_module
    return _bootstrap._gcd_import(name[level:], package, level)
  File "<frozen importlib._bootstrap>", line 1050, in _gcd_import
  File "<frozen importlib._bootstrap>", line 1027, in _find_and_load
  File "<frozen importlib._bootstrap>", line 1006, in _find_and_load_unlocked
  File "<frozen importlib._bootstrap>", line 688, in _load_unlocked
  File "<frozen importlib._bootstrap_external>", line 883, in exec_module
  File "<frozen importlib._bootstrap>", line 241, in _call_with_frames_removed
  File "/home/kc/blancexchangeapi/core_app_root/security/auth/routers.py", line 2, in <module>
    from core_app_root.security.auth.viewsets.register import RegisterViewSet
  File "/home/kc/blancexchangeapi/core_app_root/security/auth/viewsets/register.py", line 173
    await send_activation_code(request)
    ^^^^^^^^^^^^^^^^^^^^^^^^^^^^^^^^^^^
SyntaxError: 'await' outside async function
Performing system checks...

Exception in thread django-main-thread:
Traceback (most recent call last):
  File "/root/anaconda3/lib/python3.10/threading.py", line 1016, in _bootstrap_inner
    self.run()
  File "/root/anaconda3/lib/python3.10/threading.py", line 953, in run
    self._target(*self._args, **self._kwargs)
  File "/root/anaconda3/lib/python3.10/site-packages/django/utils/autoreload.py", line 64, in wrapper
    fn(*args, **kwargs)
  File "/root/anaconda3/lib/python3.10/site-packages/django/core/management/commands/runserver.py", line 133, in inner_run
    self.check(display_num_errors=True)
  File "/root/anaconda3/lib/python3.10/site-packages/django/core/management/base.py", line 485, in check
    all_issues = checks.run_checks(
  File "/root/anaconda3/lib/python3.10/site-packages/django/core/checks/registry.py", line 88, in run_checks
    new_errors = check(app_configs=app_configs, databases=databases)
  File "/root/anaconda3/lib/python3.10/site-packages/django/core/checks/urls.py", line 14, in check_url_config
    return check_resolver(resolver)
  File "/root/anaconda3/lib/python3.10/site-packages/django/core/checks/urls.py", line 24, in check_resolver
    return check_method()
  File "/root/anaconda3/lib/python3.10/site-packages/django/urls/resolvers.py", line 494, in check
    for pattern in self.url_patterns:
  File "/root/anaconda3/lib/python3.10/site-packages/django/utils/functional.py", line 57, in __get__
    res = instance.__dict__[self.name] = self.func(instance)
  File "/root/anaconda3/lib/python3.10/site-packages/django/urls/resolvers.py", line 715, in url_patterns
    patterns = getattr(self.urlconf_module, "urlpatterns", self.urlconf_module)
  File "/root/anaconda3/lib/python3.10/site-packages/django/utils/functional.py", line 57, in __get__
    res = instance.__dict__[self.name] = self.func(instance)
  File "/root/anaconda3/lib/python3.10/site-packages/django/urls/resolvers.py", line 708, in urlconf_module
    return import_module(self.urlconf_name)
  File "/root/anaconda3/lib/python3.10/importlib/__init__.py", line 126, in import_module
    return _bootstrap._gcd_import(name[level:], package, level)
  File "<frozen importlib._bootstrap>", line 1050, in _gcd_import
  File "<frozen importlib._bootstrap>", line 1027, in _find_and_load
  File "<frozen importlib._bootstrap>", line 1006, in _find_and_load_unlocked
  File "<frozen importlib._bootstrap>", line 688, in _load_unlocked
  File "<frozen importlib._bootstrap_external>", line 883, in exec_module
  File "<frozen importlib._bootstrap>", line 241, in _call_with_frames_removed
  File "/home/kc/blancexchangeapi/blankexchange/urls.py", line 44, in <module>
    path('',include(('core_app_root.security.auth.routers','core_app_root.security.auth'))),
  File "/root/anaconda3/lib/python3.10/site-packages/django/urls/conf.py", line 38, in include
    urlconf_module = import_module(urlconf_module)
  File "/root/anaconda3/lib/python3.10/importlib/__init__.py", line 126, in import_module
    return _bootstrap._gcd_import(name[level:], package, level)
  File "<frozen importlib._bootstrap>", line 1050, in _gcd_import
  File "<frozen importlib._bootstrap>", line 1027, in _find_and_load
  File "<frozen importlib._bootstrap>", line 1006, in _find_and_load_unlocked
  File "<frozen importlib._bootstrap>", line 688, in _load_unlocked
  File "<frozen importlib._bootstrap_external>", line 883, in exec_module
  File "<frozen importlib._bootstrap>", line 241, in _call_with_frames_removed
  File "/home/kc/blancexchangeapi/core_app_root/security/auth/routers.py", line 2, in <module>
    from core_app_root.security.auth.viewsets.register import RegisterViewSet
  File "/home/kc/blancexchangeapi/core_app_root/security/auth/viewsets/register.py", line 173
    await self.send_activation_code(request)
    ^^^^^^^^^^^^^^^^^^^^^^^^^^^^^^^^^^^^^^^^
SyntaxError: 'await' outside async function
Performing system checks...

Exception in thread django-main-thread:
Traceback (most recent call last):
  File "/root/anaconda3/lib/python3.10/threading.py", line 1016, in _bootstrap_inner
    self.run()
  File "/root/anaconda3/lib/python3.10/threading.py", line 953, in run
    self._target(*self._args, **self._kwargs)
  File "/root/anaconda3/lib/python3.10/site-packages/django/utils/autoreload.py", line 64, in wrapper
    fn(*args, **kwargs)
  File "/root/anaconda3/lib/python3.10/site-packages/django/core/management/commands/runserver.py", line 133, in inner_run
    self.check(display_num_errors=True)
  File "/root/anaconda3/lib/python3.10/site-packages/django/core/management/base.py", line 485, in check
    all_issues = checks.run_checks(
  File "/root/anaconda3/lib/python3.10/site-packages/django/core/checks/registry.py", line 88, in run_checks
    new_errors = check(app_configs=app_configs, databases=databases)
  File "/root/anaconda3/lib/python3.10/site-packages/django/core/checks/urls.py", line 14, in check_url_config
    return check_resolver(resolver)
  File "/root/anaconda3/lib/python3.10/site-packages/django/core/checks/urls.py", line 24, in check_resolver
    return check_method()
  File "/root/anaconda3/lib/python3.10/site-packages/django/urls/resolvers.py", line 494, in check
    for pattern in self.url_patterns:
  File "/root/anaconda3/lib/python3.10/site-packages/django/utils/functional.py", line 57, in __get__
    res = instance.__dict__[self.name] = self.func(instance)
  File "/root/anaconda3/lib/python3.10/site-packages/django/urls/resolvers.py", line 715, in url_patterns
    patterns = getattr(self.urlconf_module, "urlpatterns", self.urlconf_module)
  File "/root/anaconda3/lib/python3.10/site-packages/django/utils/functional.py", line 57, in __get__
    res = instance.__dict__[self.name] = self.func(instance)
  File "/root/anaconda3/lib/python3.10/site-packages/django/urls/resolvers.py", line 708, in urlconf_module
    return import_module(self.urlconf_name)
  File "/root/anaconda3/lib/python3.10/importlib/__init__.py", line 126, in import_module
    return _bootstrap._gcd_import(name[level:], package, level)
  File "<frozen importlib._bootstrap>", line 1050, in _gcd_import
  File "<frozen importlib._bootstrap>", line 1027, in _find_and_load
  File "<frozen importlib._bootstrap>", line 1006, in _find_and_load_unlocked
  File "<frozen importlib._bootstrap>", line 688, in _load_unlocked
  File "<frozen importlib._bootstrap_external>", line 883, in exec_module
  File "<frozen importlib._bootstrap>", line 241, in _call_with_frames_removed
  File "/home/kc/blancexchangeapi/blankexchange/urls.py", line 44, in <module>
    path('',include(('core_app_root.security.auth.routers','core_app_root.security.auth'))),
  File "/root/anaconda3/lib/python3.10/site-packages/django/urls/conf.py", line 38, in include
    urlconf_module = import_module(urlconf_module)
  File "/root/anaconda3/lib/python3.10/importlib/__init__.py", line 126, in import_module
    return _bootstrap._gcd_import(name[level:], package, level)
  File "<frozen importlib._bootstrap>", line 1050, in _gcd_import
  File "<frozen importlib._bootstrap>", line 1027, in _find_and_load
  File "<frozen importlib._bootstrap>", line 1006, in _find_and_load_unlocked
  File "<frozen importlib._bootstrap>", line 688, in _load_unlocked
  File "<frozen importlib._bootstrap_external>", line 883, in exec_module
  File "<frozen importlib._bootstrap>", line 241, in _call_with_frames_removed
  File "/home/kc/blancexchangeapi/core_app_root/security/auth/routers.py", line 2, in <module>
    from core_app_root.security.auth.viewsets.register import RegisterViewSet
  File "/home/kc/blancexchangeapi/core_app_root/security/auth/viewsets/register.py", line 33
    impot a
          ^
SyntaxError: invalid syntax
Performing system checks...

Exception in thread django-main-thread:
Traceback (most recent call last):
  File "/root/anaconda3/lib/python3.10/threading.py", line 1016, in _bootstrap_inner
    self.run()
  File "/root/anaconda3/lib/python3.10/threading.py", line 953, in run
    self._target(*self._args, **self._kwargs)
  File "/root/anaconda3/lib/python3.10/site-packages/django/utils/autoreload.py", line 64, in wrapper
    fn(*args, **kwargs)
  File "/root/anaconda3/lib/python3.10/site-packages/django/core/management/commands/runserver.py", line 133, in inner_run
    self.check(display_num_errors=True)
  File "/root/anaconda3/lib/python3.10/site-packages/django/core/management/base.py", line 485, in check
    all_issues = checks.run_checks(
  File "/root/anaconda3/lib/python3.10/site-packages/django/core/checks/registry.py", line 88, in run_checks
    new_errors = check(app_configs=app_configs, databases=databases)
  File "/root/anaconda3/lib/python3.10/site-packages/django/core/checks/urls.py", line 14, in check_url_config
    return check_resolver(resolver)
  File "/root/anaconda3/lib/python3.10/site-packages/django/core/checks/urls.py", line 24, in check_resolver
    return check_method()
  File "/root/anaconda3/lib/python3.10/site-packages/django/urls/resolvers.py", line 494, in check
    for pattern in self.url_patterns:
  File "/root/anaconda3/lib/python3.10/site-packages/django/utils/functional.py", line 57, in __get__
    res = instance.__dict__[self.name] = self.func(instance)
  File "/root/anaconda3/lib/python3.10/site-packages/django/urls/resolvers.py", line 715, in url_patterns
    patterns = getattr(self.urlconf_module, "urlpatterns", self.urlconf_module)
  File "/root/anaconda3/lib/python3.10/site-packages/django/utils/functional.py", line 57, in __get__
    res = instance.__dict__[self.name] = self.func(instance)
  File "/root/anaconda3/lib/python3.10/site-packages/django/urls/resolvers.py", line 708, in urlconf_module
    return import_module(self.urlconf_name)
  File "/root/anaconda3/lib/python3.10/importlib/__init__.py", line 126, in import_module
    return _bootstrap._gcd_import(name[level:], package, level)
  File "<frozen importlib._bootstrap>", line 1050, in _gcd_import
  File "<frozen importlib._bootstrap>", line 1027, in _find_and_load
  File "<frozen importlib._bootstrap>", line 1006, in _find_and_load_unlocked
  File "<frozen importlib._bootstrap>", line 688, in _load_unlocked
  File "<frozen importlib._bootstrap_external>", line 883, in exec_module
  File "<frozen importlib._bootstrap>", line 241, in _call_with_frames_removed
  File "/home/kc/blancexchangeapi/blankexchange/urls.py", line 44, in <module>
    path('',include(('core_app_root.security.auth.routers','core_app_root.security.auth'))),
  File "/root/anaconda3/lib/python3.10/site-packages/django/urls/conf.py", line 38, in include
    urlconf_module = import_module(urlconf_module)
  File "/root/anaconda3/lib/python3.10/importlib/__init__.py", line 126, in import_module
    return _bootstrap._gcd_import(name[level:], package, level)
  File "<frozen importlib._bootstrap>", line 1050, in _gcd_import
  File "<frozen importlib._bootstrap>", line 1027, in _find_and_load
  File "<frozen importlib._bootstrap>", line 1006, in _find_and_load_unlocked
  File "<frozen importlib._bootstrap>", line 688, in _load_unlocked
  File "<frozen importlib._bootstrap_external>", line 883, in exec_module
  File "<frozen importlib._bootstrap>", line 241, in _call_with_frames_removed
  File "/home/kc/blancexchangeapi/core_app_root/security/auth/routers.py", line 2, in <module>
    from core_app_root.security.auth.viewsets.register import RegisterViewSet
  File "/home/kc/blancexchangeapi/core_app_root/security/auth/viewsets/register.py", line 33
    import async
           ^^^^^
SyntaxError: invalid syntax
Performing system checks...

Exception in thread django-main-thread:
Traceback (most recent call last):
  File "/root/anaconda3/lib/python3.10/threading.py", line 1016, in _bootstrap_inner
    self.run()
  File "/root/anaconda3/lib/python3.10/threading.py", line 953, in run
    self._target(*self._args, **self._kwargs)
  File "/root/anaconda3/lib/python3.10/site-packages/django/utils/autoreload.py", line 64, in wrapper
    fn(*args, **kwargs)
  File "/root/anaconda3/lib/python3.10/site-packages/django/core/management/commands/runserver.py", line 133, in inner_run
    self.check(display_num_errors=True)
  File "/root/anaconda3/lib/python3.10/site-packages/django/core/management/base.py", line 485, in check
    all_issues = checks.run_checks(
  File "/root/anaconda3/lib/python3.10/site-packages/django/core/checks/registry.py", line 88, in run_checks
    new_errors = check(app_configs=app_configs, databases=databases)
  File "/root/anaconda3/lib/python3.10/site-packages/django/core/checks/urls.py", line 14, in check_url_config
    return check_resolver(resolver)
  File "/root/anaconda3/lib/python3.10/site-packages/django/core/checks/urls.py", line 24, in check_resolver
    return check_method()
  File "/root/anaconda3/lib/python3.10/site-packages/django/urls/resolvers.py", line 494, in check
    for pattern in self.url_patterns:
  File "/root/anaconda3/lib/python3.10/site-packages/django/utils/functional.py", line 57, in __get__
    res = instance.__dict__[self.name] = self.func(instance)
  File "/root/anaconda3/lib/python3.10/site-packages/django/urls/resolvers.py", line 715, in url_patterns
    patterns = getattr(self.urlconf_module, "urlpatterns", self.urlconf_module)
  File "/root/anaconda3/lib/python3.10/site-packages/django/utils/functional.py", line 57, in __get__
    res = instance.__dict__[self.name] = self.func(instance)
  File "/root/anaconda3/lib/python3.10/site-packages/django/urls/resolvers.py", line 708, in urlconf_module
    return import_module(self.urlconf_name)
  File "/root/anaconda3/lib/python3.10/importlib/__init__.py", line 126, in import_module
    return _bootstrap._gcd_import(name[level:], package, level)
  File "<frozen importlib._bootstrap>", line 1050, in _gcd_import
  File "<frozen importlib._bootstrap>", line 1027, in _find_and_load
  File "<frozen importlib._bootstrap>", line 1006, in _find_and_load_unlocked
  File "<frozen importlib._bootstrap>", line 688, in _load_unlocked
  File "<frozen importlib._bootstrap_external>", line 883, in exec_module
  File "<frozen importlib._bootstrap>", line 241, in _call_with_frames_removed
  File "/home/kc/blancexchangeapi/blankexchange/urls.py", line 44, in <module>
    path('',include(('core_app_root.security.auth.routers','core_app_root.security.auth'))),
  File "/root/anaconda3/lib/python3.10/site-packages/django/urls/conf.py", line 38, in include
    urlconf_module = import_module(urlconf_module)
  File "/root/anaconda3/lib/python3.10/importlib/__init__.py", line 126, in import_module
    return _bootstrap._gcd_import(name[level:], package, level)
  File "<frozen importlib._bootstrap>", line 1050, in _gcd_import
  File "<frozen importlib._bootstrap>", line 1027, in _find_and_load
  File "<frozen importlib._bootstrap>", line 1006, in _find_and_load_unlocked
  File "<frozen importlib._bootstrap>", line 688, in _load_unlocked
  File "<frozen importlib._bootstrap_external>", line 883, in exec_module
  File "<frozen importlib._bootstrap>", line 241, in _call_with_frames_removed
  File "/home/kc/blancexchangeapi/core_app_root/security/auth/routers.py", line 2, in <module>
    from core_app_root.security.auth.viewsets.register import RegisterViewSet
  File "/home/kc/blancexchangeapi/core_app_root/security/auth/viewsets/register.py", line 174
    await self.send_activation_code(request)
    ^^^^^^^^^^^^^^^^^^^^^^^^^^^^^^^^^^^^^^^^
SyntaxError: 'await' outside async function
Performing system checks...

Exception in thread django-main-thread:
Traceback (most recent call last):
  File "/root/anaconda3/lib/python3.10/threading.py", line 1016, in _bootstrap_inner
    self.run()
  File "/root/anaconda3/lib/python3.10/threading.py", line 953, in run
    self._target(*self._args, **self._kwargs)
  File "/root/anaconda3/lib/python3.10/site-packages/django/utils/autoreload.py", line 64, in wrapper
    fn(*args, **kwargs)
  File "/root/anaconda3/lib/python3.10/site-packages/django/core/management/commands/runserver.py", line 133, in inner_run
    self.check(display_num_errors=True)
  File "/root/anaconda3/lib/python3.10/site-packages/django/core/management/base.py", line 485, in check
    all_issues = checks.run_checks(
  File "/root/anaconda3/lib/python3.10/site-packages/django/core/checks/registry.py", line 88, in run_checks
    new_errors = check(app_configs=app_configs, databases=databases)
  File "/root/anaconda3/lib/python3.10/site-packages/django/core/checks/urls.py", line 14, in check_url_config
    return check_resolver(resolver)
  File "/root/anaconda3/lib/python3.10/site-packages/django/core/checks/urls.py", line 24, in check_resolver
    return check_method()
  File "/root/anaconda3/lib/python3.10/site-packages/django/urls/resolvers.py", line 494, in check
    for pattern in self.url_patterns:
  File "/root/anaconda3/lib/python3.10/site-packages/django/utils/functional.py", line 57, in __get__
    res = instance.__dict__[self.name] = self.func(instance)
  File "/root/anaconda3/lib/python3.10/site-packages/django/urls/resolvers.py", line 715, in url_patterns
    patterns = getattr(self.urlconf_module, "urlpatterns", self.urlconf_module)
  File "/root/anaconda3/lib/python3.10/site-packages/django/utils/functional.py", line 57, in __get__
    res = instance.__dict__[self.name] = self.func(instance)
  File "/root/anaconda3/lib/python3.10/site-packages/django/urls/resolvers.py", line 708, in urlconf_module
    return import_module(self.urlconf_name)
  File "/root/anaconda3/lib/python3.10/importlib/__init__.py", line 126, in import_module
    return _bootstrap._gcd_import(name[level:], package, level)
  File "<frozen importlib._bootstrap>", line 1050, in _gcd_import
  File "<frozen importlib._bootstrap>", line 1027, in _find_and_load
  File "<frozen importlib._bootstrap>", line 1006, in _find_and_load_unlocked
  File "<frozen importlib._bootstrap>", line 688, in _load_unlocked
  File "<frozen importlib._bootstrap_external>", line 883, in exec_module
  File "<frozen importlib._bootstrap>", line 241, in _call_with_frames_removed
  File "/home/kc/blancexchangeapi/blankexchange/urls.py", line 44, in <module>
    path('',include(('core_app_root.security.auth.routers','core_app_root.security.auth'))),
  File "/root/anaconda3/lib/python3.10/site-packages/django/urls/conf.py", line 38, in include
    urlconf_module = import_module(urlconf_module)
  File "/root/anaconda3/lib/python3.10/importlib/__init__.py", line 126, in import_module
    return _bootstrap._gcd_import(name[level:], package, level)
  File "<frozen importlib._bootstrap>", line 1050, in _gcd_import
  File "<frozen importlib._bootstrap>", line 1027, in _find_and_load
  File "<frozen importlib._bootstrap>", line 1006, in _find_and_load_unlocked
  File "<frozen importlib._bootstrap>", line 688, in _load_unlocked
  File "<frozen importlib._bootstrap_external>", line 883, in exec_module
  File "<frozen importlib._bootstrap>", line 241, in _call_with_frames_removed
  File "/home/kc/blancexchangeapi/core_app_root/security/auth/routers.py", line 2, in <module>
    from core_app_root.security.auth.viewsets.register import RegisterViewSet
  File "/home/kc/blancexchangeapi/core_app_root/security/auth/viewsets/register.py", line 174
    await self.send_activation_code(request)
    ^^^^^^^^^^^^^^^^^^^^^^^^^^^^^^^^^^^^^^^^
SyntaxError: 'await' outside async function
Performing system checks...

Exception in thread django-main-thread:
Traceback (most recent call last):
  File "/root/anaconda3/lib/python3.10/threading.py", line 1016, in _bootstrap_inner
    self.run()
  File "/root/anaconda3/lib/python3.10/threading.py", line 953, in run
    self._target(*self._args, **self._kwargs)
  File "/root/anaconda3/lib/python3.10/site-packages/django/utils/autoreload.py", line 64, in wrapper
    fn(*args, **kwargs)
  File "/root/anaconda3/lib/python3.10/site-packages/django/core/management/commands/runserver.py", line 133, in inner_run
    self.check(display_num_errors=True)
  File "/root/anaconda3/lib/python3.10/site-packages/django/core/management/base.py", line 485, in check
    all_issues = checks.run_checks(
  File "/root/anaconda3/lib/python3.10/site-packages/django/core/checks/registry.py", line 88, in run_checks
    new_errors = check(app_configs=app_configs, databases=databases)
  File "/root/anaconda3/lib/python3.10/site-packages/django/core/checks/urls.py", line 14, in check_url_config
    return check_resolver(resolver)
  File "/root/anaconda3/lib/python3.10/site-packages/django/core/checks/urls.py", line 24, in check_resolver
    return check_method()
  File "/root/anaconda3/lib/python3.10/site-packages/django/urls/resolvers.py", line 494, in check
    for pattern in self.url_patterns:
  File "/root/anaconda3/lib/python3.10/site-packages/django/utils/functional.py", line 57, in __get__
    res = instance.__dict__[self.name] = self.func(instance)
  File "/root/anaconda3/lib/python3.10/site-packages/django/urls/resolvers.py", line 715, in url_patterns
    patterns = getattr(self.urlconf_module, "urlpatterns", self.urlconf_module)
  File "/root/anaconda3/lib/python3.10/site-packages/django/utils/functional.py", line 57, in __get__
    res = instance.__dict__[self.name] = self.func(instance)
  File "/root/anaconda3/lib/python3.10/site-packages/django/urls/resolvers.py", line 708, in urlconf_module
    return import_module(self.urlconf_name)
  File "/root/anaconda3/lib/python3.10/importlib/__init__.py", line 126, in import_module
    return _bootstrap._gcd_import(name[level:], package, level)
  File "<frozen importlib._bootstrap>", line 1050, in _gcd_import
  File "<frozen importlib._bootstrap>", line 1027, in _find_and_load
  File "<frozen importlib._bootstrap>", line 1006, in _find_and_load_unlocked
  File "<frozen importlib._bootstrap>", line 688, in _load_unlocked
  File "<frozen importlib._bootstrap_external>", line 883, in exec_module
  File "<frozen importlib._bootstrap>", line 241, in _call_with_frames_removed
  File "/home/kc/blancexchangeapi/blankexchange/urls.py", line 44, in <module>
    path('',include(('core_app_root.security.auth.routers','core_app_root.security.auth'))),
  File "/root/anaconda3/lib/python3.10/site-packages/django/urls/conf.py", line 38, in include
    urlconf_module = import_module(urlconf_module)
  File "/root/anaconda3/lib/python3.10/importlib/__init__.py", line 126, in import_module
    return _bootstrap._gcd_import(name[level:], package, level)
  File "<frozen importlib._bootstrap>", line 1050, in _gcd_import
  File "<frozen importlib._bootstrap>", line 1027, in _find_and_load
  File "<frozen importlib._bootstrap>", line 1006, in _find_and_load_unlocked
  File "<frozen importlib._bootstrap>", line 688, in _load_unlocked
  File "<frozen importlib._bootstrap_external>", line 883, in exec_module
  File "<frozen importlib._bootstrap>", line 241, in _call_with_frames_removed
  File "/home/kc/blancexchangeapi/core_app_root/security/auth/routers.py", line 2, in <module>
    from core_app_root.security.auth.viewsets.register import RegisterViewSet
  File "/home/kc/blancexchangeapi/core_app_root/security/auth/viewsets/register.py", line 174
    await self.send_activation_code(request)
    ^^^^^^^^^^^^^^^^^^^^^^^^^^^^^^^^^^^^^^^^
SyntaxError: 'await' outside async function
Performing system checks...

Exception in thread django-main-thread:
Traceback (most recent call last):
  File "/root/anaconda3/lib/python3.10/threading.py", line 1016, in _bootstrap_inner
    self.run()
  File "/root/anaconda3/lib/python3.10/threading.py", line 953, in run
    self._target(*self._args, **self._kwargs)
  File "/root/anaconda3/lib/python3.10/site-packages/django/utils/autoreload.py", line 64, in wrapper
    fn(*args, **kwargs)
  File "/root/anaconda3/lib/python3.10/site-packages/django/core/management/commands/runserver.py", line 133, in inner_run
    self.check(display_num_errors=True)
  File "/root/anaconda3/lib/python3.10/site-packages/django/core/management/base.py", line 485, in check
    all_issues = checks.run_checks(
  File "/root/anaconda3/lib/python3.10/site-packages/django/core/checks/registry.py", line 88, in run_checks
    new_errors = check(app_configs=app_configs, databases=databases)
  File "/root/anaconda3/lib/python3.10/site-packages/django/core/checks/urls.py", line 14, in check_url_config
    return check_resolver(resolver)
  File "/root/anaconda3/lib/python3.10/site-packages/django/core/checks/urls.py", line 24, in check_resolver
    return check_method()
  File "/root/anaconda3/lib/python3.10/site-packages/django/urls/resolvers.py", line 494, in check
    for pattern in self.url_patterns:
  File "/root/anaconda3/lib/python3.10/site-packages/django/utils/functional.py", line 57, in __get__
    res = instance.__dict__[self.name] = self.func(instance)
  File "/root/anaconda3/lib/python3.10/site-packages/django/urls/resolvers.py", line 715, in url_patterns
    patterns = getattr(self.urlconf_module, "urlpatterns", self.urlconf_module)
  File "/root/anaconda3/lib/python3.10/site-packages/django/utils/functional.py", line 57, in __get__
    res = instance.__dict__[self.name] = self.func(instance)
  File "/root/anaconda3/lib/python3.10/site-packages/django/urls/resolvers.py", line 708, in urlconf_module
    return import_module(self.urlconf_name)
  File "/root/anaconda3/lib/python3.10/importlib/__init__.py", line 126, in import_module
    return _bootstrap._gcd_import(name[level:], package, level)
  File "<frozen importlib._bootstrap>", line 1050, in _gcd_import
  File "<frozen importlib._bootstrap>", line 1027, in _find_and_load
  File "<frozen importlib._bootstrap>", line 1006, in _find_and_load_unlocked
  File "<frozen importlib._bootstrap>", line 688, in _load_unlocked
  File "<frozen importlib._bootstrap_external>", line 883, in exec_module
  File "<frozen importlib._bootstrap>", line 241, in _call_with_frames_removed
  File "/home/kc/blancexchangeapi/blankexchange/urls.py", line 44, in <module>
    path('',include(('core_app_root.security.auth.routers','core_app_root.security.auth'))),
  File "/root/anaconda3/lib/python3.10/site-packages/django/urls/conf.py", line 38, in include
    urlconf_module = import_module(urlconf_module)
  File "/root/anaconda3/lib/python3.10/importlib/__init__.py", line 126, in import_module
    return _bootstrap._gcd_import(name[level:], package, level)
  File "<frozen importlib._bootstrap>", line 1050, in _gcd_import
  File "<frozen importlib._bootstrap>", line 1027, in _find_and_load
  File "<frozen importlib._bootstrap>", line 1006, in _find_and_load_unlocked
  File "<frozen importlib._bootstrap>", line 688, in _load_unlocked
  File "<frozen importlib._bootstrap_external>", line 883, in exec_module
  File "<frozen importlib._bootstrap>", line 241, in _call_with_frames_removed
  File "/home/kc/blancexchangeapi/core_app_root/security/auth/routers.py", line 2, in <module>
    from core_app_root.security.auth.viewsets.register import RegisterViewSet
  File "/home/kc/blancexchangeapi/core_app_root/security/auth/viewsets/register.py", line 174
    await self.send_activation_code(request)
    ^^^^^^^^^^^^^^^^^^^^^^^^^^^^^^^^^^^^^^^^
SyntaxError: 'await' outside async function
Performing system checks...

System check identified no issues (0 silenced).
June 15, 2024 - 15:03:26
Django version 4.2.11, using settings 'blankexchange.settings'
Starting development server at http://192.81.210.127:9000/
Quit the server with CONTROL-C.

Performing system checks...

System check identified no issues (0 silenced).
June 15, 2024 - 15:03:38
Django version 4.2.11, using settings 'blankexchange.settings'
Starting development server at http://192.81.210.127:9000/
Quit the server with CONTROL-C.

Performing system checks...

System check identified no issues (0 silenced).
June 15, 2024 - 15:19:55
Django version 4.2.11, using settings 'blankexchange.settings'
Starting development server at http://192.81.210.127:9000/
Quit the server with CONTROL-C.

Performing system checks...

System check identified no issues (0 silenced).
June 15, 2024 - 17:07:43
Django version 4.2.11, using settings 'blankexchange.settings'
Starting development server at http://192.81.210.127:9000/
Quit the server with CONTROL-C.

Performing system checks...

System check identified no issues (0 silenced).
June 15, 2024 - 17:07:46
Django version 4.2.11, using settings 'blankexchange.settings'
Starting development server at http://192.81.210.127:9000/
Quit the server with CONTROL-C.

Performing system checks...

System check identified no issues (0 silenced).
June 15, 2024 - 17:08:23
Django version 4.2.11, using settings 'blankexchange.settings'
Starting development server at http://192.81.210.127:9000/
Quit the server with CONTROL-C.

Performing system checks...

System check identified no issues (0 silenced).
June 15, 2024 - 17:08:58
Django version 4.2.11, using settings 'blankexchange.settings'
Starting development server at http://192.81.210.127:9000/
Quit the server with CONTROL-C.

Performing system checks...

System check identified no issues (0 silenced).
June 15, 2024 - 17:09:03
Django version 4.2.11, using settings 'blankexchange.settings'
Starting development server at http://192.81.210.127:9000/
Quit the server with CONTROL-C.

Performing system checks...

System check identified no issues (0 silenced).
June 15, 2024 - 17:12:44
Django version 4.2.11, using settings 'blankexchange.settings'
Starting development server at http://192.81.210.127:9000/
Quit the server with CONTROL-C.

Performing system checks...

System check identified no issues (0 silenced).
June 15, 2024 - 17:12:48
Django version 4.2.11, using settings 'blankexchange.settings'
Starting development server at http://192.81.210.127:9000/
Quit the server with CONTROL-C.

Performing system checks...

System check identified no issues (0 silenced).
June 15, 2024 - 17:12:59
Django version 4.2.11, using settings 'blankexchange.settings'
Starting development server at http://192.81.210.127:9000/
Quit the server with CONTROL-C.

Performing system checks...

System check identified no issues (0 silenced).
June 15, 2024 - 17:13:59
Django version 4.2.11, using settings 'blankexchange.settings'
Starting development server at http://192.81.210.127:9000/
Quit the server with CONTROL-C.

Traceback (most recent call last):
  File "/home/kc/blancexchangeapi/manage.py", line 22, in <module>
    main()
  File "/home/kc/blancexchangeapi/manage.py", line 18, in main
    execute_from_command_line(sys.argv)
  File "/root/anaconda3/lib/python3.10/site-packages/django/core/management/__init__.py", line 442, in execute_from_command_line
    utility.execute()
  File "/root/anaconda3/lib/python3.10/site-packages/django/core/management/__init__.py", line 382, in execute
    settings.INSTALLED_APPS
  File "/root/anaconda3/lib/python3.10/site-packages/django/conf/__init__.py", line 102, in __getattr__
    self._setup(name)
  File "/root/anaconda3/lib/python3.10/site-packages/django/conf/__init__.py", line 89, in _setup
    self._wrapped = Settings(settings_module)
  File "/root/anaconda3/lib/python3.10/site-packages/django/conf/__init__.py", line 217, in __init__
    mod = importlib.import_module(self.SETTINGS_MODULE)
  File "/root/anaconda3/lib/python3.10/importlib/__init__.py", line 126, in import_module
    return _bootstrap._gcd_import(name[level:], package, level)
  File "<frozen importlib._bootstrap>", line 1050, in _gcd_import
  File "<frozen importlib._bootstrap>", line 1027, in _find_and_load
  File "<frozen importlib._bootstrap>", line 1006, in _find_and_load_unlocked
  File "<frozen importlib._bootstrap>", line 688, in _load_unlocked
  File "<frozen importlib._bootstrap_external>", line 879, in exec_module
  File "<frozen importlib._bootstrap_external>", line 1017, in get_code
  File "<frozen importlib._bootstrap_external>", line 947, in source_to_code
  File "<frozen importlib._bootstrap>", line 241, in _call_with_frames_removed
  File "/home/kc/blancexchangeapi/blankexchange/settings.py", line 236
    EMAIL_USE_SSL = 
                    ^
SyntaxError: invalid syntax
Performing system checks...

System check identified no issues (0 silenced).
June 17, 2024 - 00:49:08
Django version 4.2.11, using settings 'blankexchange.settings'
Starting development server at http://192.81.210.127:1234/
Quit the server with CONTROL-C.

Performing system checks...

System check identified no issues (0 silenced).
June 17, 2024 - 00:49:31
Django version 4.2.11, using settings 'blankexchange.settings'
Starting development server at http://192.81.210.127:1234/
Quit the server with CONTROL-C.

Performing system checks...

System check identified no issues (0 silenced).
June 17, 2024 - 00:53:06
Django version 4.2.11, using settings 'blankexchange.settings'
Starting development server at http://192.81.210.127:1234/
Quit the server with CONTROL-C.

Performing system checks...

Exception in thread django-main-thread:
Traceback (most recent call last):
  File "/root/anaconda3/lib/python3.10/threading.py", line 1016, in _bootstrap_inner
    self.run()
  File "/root/anaconda3/lib/python3.10/threading.py", line 953, in run
    self._target(*self._args, **self._kwargs)
  File "/root/anaconda3/lib/python3.10/site-packages/django/utils/autoreload.py", line 64, in wrapper
    fn(*args, **kwargs)
  File "/root/anaconda3/lib/python3.10/site-packages/django/core/management/commands/runserver.py", line 133, in inner_run
    self.check(display_num_errors=True)
  File "/root/anaconda3/lib/python3.10/site-packages/django/core/management/base.py", line 485, in check
    all_issues = checks.run_checks(
  File "/root/anaconda3/lib/python3.10/site-packages/django/core/checks/registry.py", line 88, in run_checks
    new_errors = check(app_configs=app_configs, databases=databases)
  File "/root/anaconda3/lib/python3.10/site-packages/django/core/checks/urls.py", line 14, in check_url_config
    return check_resolver(resolver)
  File "/root/anaconda3/lib/python3.10/site-packages/django/core/checks/urls.py", line 24, in check_resolver
    return check_method()
  File "/root/anaconda3/lib/python3.10/site-packages/django/urls/resolvers.py", line 494, in check
    for pattern in self.url_patterns:
  File "/root/anaconda3/lib/python3.10/site-packages/django/utils/functional.py", line 57, in __get__
    res = instance.__dict__[self.name] = self.func(instance)
  File "/root/anaconda3/lib/python3.10/site-packages/django/urls/resolvers.py", line 715, in url_patterns
    patterns = getattr(self.urlconf_module, "urlpatterns", self.urlconf_module)
  File "/root/anaconda3/lib/python3.10/site-packages/django/utils/functional.py", line 57, in __get__
    res = instance.__dict__[self.name] = self.func(instance)
  File "/root/anaconda3/lib/python3.10/site-packages/django/urls/resolvers.py", line 708, in urlconf_module
    return import_module(self.urlconf_name)
  File "/root/anaconda3/lib/python3.10/importlib/__init__.py", line 126, in import_module
    return _bootstrap._gcd_import(name[level:], package, level)
  File "<frozen importlib._bootstrap>", line 1050, in _gcd_import
  File "<frozen importlib._bootstrap>", line 1027, in _find_and_load
  File "<frozen importlib._bootstrap>", line 1006, in _find_and_load_unlocked
  File "<frozen importlib._bootstrap>", line 688, in _load_unlocked
  File "<frozen importlib._bootstrap_external>", line 883, in exec_module
  File "<frozen importlib._bootstrap>", line 241, in _call_with_frames_removed
  File "/home/kc/blancexchangeapi/blankexchange/urls.py", line 45, in <module>
    path('bank/',include(('core_app_root.user_services.bankmanagement.routers','core_app_root.user_services.bankmanagement'))),
  File "/root/anaconda3/lib/python3.10/site-packages/django/urls/conf.py", line 38, in include
    urlconf_module = import_module(urlconf_module)
  File "/root/anaconda3/lib/python3.10/importlib/__init__.py", line 126, in import_module
    return _bootstrap._gcd_import(name[level:], package, level)
  File "<frozen importlib._bootstrap>", line 1050, in _gcd_import
  File "<frozen importlib._bootstrap>", line 1027, in _find_and_load
  File "<frozen importlib._bootstrap>", line 1006, in _find_and_load_unlocked
  File "<frozen importlib._bootstrap>", line 688, in _load_unlocked
  File "<frozen importlib._bootstrap_external>", line 883, in exec_module
  File "<frozen importlib._bootstrap>", line 241, in _call_with_frames_removed
  File "/home/kc/blancexchangeapi/core_app_root/user_services/bankmanagement/routers.py", line 2, in <module>
    from core_app_root.user_services.bankmanagement.viewsets.bankmanagementviewset import BankManagementViewset,UserBankDetailsViewset
  File "/home/kc/blancexchangeapi/core_app_root/user_services/bankmanagement/viewsets/bankmanagementviewset.py", line 40
    load_dotenv()
IndentationError: expected an indented block after 'if' statement on line 36
Performing system checks...

Exception in thread django-main-thread:
Traceback (most recent call last):
  File "/root/anaconda3/lib/python3.10/threading.py", line 1016, in _bootstrap_inner
    self.run()
  File "/root/anaconda3/lib/python3.10/threading.py", line 953, in run
    self._target(*self._args, **self._kwargs)
  File "/root/anaconda3/lib/python3.10/site-packages/django/utils/autoreload.py", line 64, in wrapper
    fn(*args, **kwargs)
  File "/root/anaconda3/lib/python3.10/site-packages/django/core/management/commands/runserver.py", line 133, in inner_run
    self.check(display_num_errors=True)
  File "/root/anaconda3/lib/python3.10/site-packages/django/core/management/base.py", line 485, in check
    all_issues = checks.run_checks(
  File "/root/anaconda3/lib/python3.10/site-packages/django/core/checks/registry.py", line 88, in run_checks
    new_errors = check(app_configs=app_configs, databases=databases)
  File "/root/anaconda3/lib/python3.10/site-packages/django/core/checks/urls.py", line 14, in check_url_config
    return check_resolver(resolver)
  File "/root/anaconda3/lib/python3.10/site-packages/django/core/checks/urls.py", line 24, in check_resolver
    return check_method()
  File "/root/anaconda3/lib/python3.10/site-packages/django/urls/resolvers.py", line 494, in check
    for pattern in self.url_patterns:
  File "/root/anaconda3/lib/python3.10/site-packages/django/utils/functional.py", line 57, in __get__
    res = instance.__dict__[self.name] = self.func(instance)
  File "/root/anaconda3/lib/python3.10/site-packages/django/urls/resolvers.py", line 715, in url_patterns
    patterns = getattr(self.urlconf_module, "urlpatterns", self.urlconf_module)
  File "/root/anaconda3/lib/python3.10/site-packages/django/utils/functional.py", line 57, in __get__
    res = instance.__dict__[self.name] = self.func(instance)
  File "/root/anaconda3/lib/python3.10/site-packages/django/urls/resolvers.py", line 708, in urlconf_module
    return import_module(self.urlconf_name)
  File "/root/anaconda3/lib/python3.10/importlib/__init__.py", line 126, in import_module
    return _bootstrap._gcd_import(name[level:], package, level)
  File "<frozen importlib._bootstrap>", line 1050, in _gcd_import
  File "<frozen importlib._bootstrap>", line 1027, in _find_and_load
  File "<frozen importlib._bootstrap>", line 1006, in _find_and_load_unlocked
  File "<frozen importlib._bootstrap>", line 688, in _load_unlocked
  File "<frozen importlib._bootstrap_external>", line 883, in exec_module
  File "<frozen importlib._bootstrap>", line 241, in _call_with_frames_removed
  File "/home/kc/blancexchangeapi/blankexchange/urls.py", line 45, in <module>
    path('bank/',include(('core_app_root.user_services.bankmanagement.routers','core_app_root.user_services.bankmanagement'))),
  File "/root/anaconda3/lib/python3.10/site-packages/django/urls/conf.py", line 38, in include
    urlconf_module = import_module(urlconf_module)
  File "/root/anaconda3/lib/python3.10/importlib/__init__.py", line 126, in import_module
    return _bootstrap._gcd_import(name[level:], package, level)
  File "<frozen importlib._bootstrap>", line 1050, in _gcd_import
  File "<frozen importlib._bootstrap>", line 1027, in _find_and_load
  File "<frozen importlib._bootstrap>", line 1006, in _find_and_load_unlocked
  File "<frozen importlib._bootstrap>", line 688, in _load_unlocked
  File "<frozen importlib._bootstrap_external>", line 883, in exec_module
  File "<frozen importlib._bootstrap>", line 241, in _call_with_frames_removed
  File "/home/kc/blancexchangeapi/core_app_root/user_services/bankmanagement/routers.py", line 2, in <module>
    from core_app_root.user_services.bankmanagement.viewsets.bankmanagementviewset import BankManagementViewset,UserBankDetailsViewset
  File "/home/kc/blancexchangeapi/core_app_root/user_services/bankmanagement/viewsets/bankmanagementviewset.py", line 40
    load_dotenv()
    ^
IndentationError: expected an indented block after 'if' statement on line 36
Performing system checks...

System check identified no issues (0 silenced).
June 17, 2024 - 01:15:50
Django version 4.2.11, using settings 'blankexchange.settings'
Starting development server at http://192.81.210.127:1234/
Quit the server with CONTROL-C.

Performing system checks...

System check identified no issues (0 silenced).
June 17, 2024 - 01:15:59
Django version 4.2.11, using settings 'blankexchange.settings'
Starting development server at http://192.81.210.127:1234/
Quit the server with CONTROL-C.

Performing system checks...

Exception in thread django-main-thread:
Traceback (most recent call last):
  File "/root/anaconda3/lib/python3.10/threading.py", line 1016, in _bootstrap_inner
    self.run()
  File "/root/anaconda3/lib/python3.10/threading.py", line 953, in run
    self._target(*self._args, **self._kwargs)
  File "/root/anaconda3/lib/python3.10/site-packages/django/utils/autoreload.py", line 64, in wrapper
    fn(*args, **kwargs)
  File "/root/anaconda3/lib/python3.10/site-packages/django/core/management/commands/runserver.py", line 133, in inner_run
    self.check(display_num_errors=True)
  File "/root/anaconda3/lib/python3.10/site-packages/django/core/management/base.py", line 485, in check
    all_issues = checks.run_checks(
  File "/root/anaconda3/lib/python3.10/site-packages/django/core/checks/registry.py", line 88, in run_checks
    new_errors = check(app_configs=app_configs, databases=databases)
  File "/root/anaconda3/lib/python3.10/site-packages/django/core/checks/urls.py", line 14, in check_url_config
    return check_resolver(resolver)
  File "/root/anaconda3/lib/python3.10/site-packages/django/core/checks/urls.py", line 24, in check_resolver
    return check_method()
  File "/root/anaconda3/lib/python3.10/site-packages/django/urls/resolvers.py", line 494, in check
    for pattern in self.url_patterns:
  File "/root/anaconda3/lib/python3.10/site-packages/django/utils/functional.py", line 57, in __get__
    res = instance.__dict__[self.name] = self.func(instance)
  File "/root/anaconda3/lib/python3.10/site-packages/django/urls/resolvers.py", line 715, in url_patterns
    patterns = getattr(self.urlconf_module, "urlpatterns", self.urlconf_module)
  File "/root/anaconda3/lib/python3.10/site-packages/django/utils/functional.py", line 57, in __get__
    res = instance.__dict__[self.name] = self.func(instance)
  File "/root/anaconda3/lib/python3.10/site-packages/django/urls/resolvers.py", line 708, in urlconf_module
    return import_module(self.urlconf_name)
  File "/root/anaconda3/lib/python3.10/importlib/__init__.py", line 126, in import_module
    return _bootstrap._gcd_import(name[level:], package, level)
  File "<frozen importlib._bootstrap>", line 1050, in _gcd_import
  File "<frozen importlib._bootstrap>", line 1027, in _find_and_load
  File "<frozen importlib._bootstrap>", line 1006, in _find_and_load_unlocked
  File "<frozen importlib._bootstrap>", line 688, in _load_unlocked
  File "<frozen importlib._bootstrap_external>", line 883, in exec_module
  File "<frozen importlib._bootstrap>", line 241, in _call_with_frames_removed
  File "/home/kc/blancexchangeapi/blankexchange/urls.py", line 45, in <module>
    path('bank/',include(('core_app_root.user_services.bankmanagement.routers','core_app_root.user_services.bankmanagement'))),
  File "/root/anaconda3/lib/python3.10/site-packages/django/urls/conf.py", line 38, in include
    urlconf_module = import_module(urlconf_module)
  File "/root/anaconda3/lib/python3.10/importlib/__init__.py", line 126, in import_module
    return _bootstrap._gcd_import(name[level:], package, level)
  File "<frozen importlib._bootstrap>", line 1050, in _gcd_import
  File "<frozen importlib._bootstrap>", line 1027, in _find_and_load
  File "<frozen importlib._bootstrap>", line 1006, in _find_and_load_unlocked
  File "<frozen importlib._bootstrap>", line 688, in _load_unlocked
  File "<frozen importlib._bootstrap_external>", line 883, in exec_module
  File "<frozen importlib._bootstrap>", line 241, in _call_with_frames_removed
  File "/home/kc/blancexchangeapi/core_app_root/user_services/bankmanagement/routers.py", line 2, in <module>
    from core_app_root.user_services.bankmanagement.viewsets.bankmanagementviewset import BankManagementViewset,UserBankDetailsViewset
  File "/home/kc/blancexchangeapi/core_app_root/user_services/bankmanagement/viewsets/bankmanagementviewset.py", line 52
    'account_number': ,
                    ^
SyntaxError: expression expected after dictionary key and ':'
Performing system checks...

System check identified no issues (0 silenced).
June 17, 2024 - 01:16:18
Django version 4.2.11, using settings 'blankexchange.settings'
Starting development server at http://192.81.210.127:1234/
Quit the server with CONTROL-C.

Performing system checks...

System check identified no issues (0 silenced).
June 17, 2024 - 01:16:23
Django version 4.2.11, using settings 'blankexchange.settings'
Starting development server at http://192.81.210.127:1234/
Quit the server with CONTROL-C.

Performing system checks...

System check identified no issues (0 silenced).
June 17, 2024 - 01:16:28
Django version 4.2.11, using settings 'blankexchange.settings'
Starting development server at http://192.81.210.127:1234/
Quit the server with CONTROL-C.

Performing system checks...

Exception in thread django-main-thread:
Traceback (most recent call last):
  File "/root/anaconda3/lib/python3.10/threading.py", line 1016, in _bootstrap_inner
    self.run()
  File "/root/anaconda3/lib/python3.10/threading.py", line 953, in run
    self._target(*self._args, **self._kwargs)
  File "/root/anaconda3/lib/python3.10/site-packages/django/utils/autoreload.py", line 64, in wrapper
    fn(*args, **kwargs)
  File "/root/anaconda3/lib/python3.10/site-packages/django/core/management/commands/runserver.py", line 133, in inner_run
    self.check(display_num_errors=True)
  File "/root/anaconda3/lib/python3.10/site-packages/django/core/management/base.py", line 485, in check
    all_issues = checks.run_checks(
  File "/root/anaconda3/lib/python3.10/site-packages/django/core/checks/registry.py", line 88, in run_checks
    new_errors = check(app_configs=app_configs, databases=databases)
  File "/root/anaconda3/lib/python3.10/site-packages/django/core/checks/urls.py", line 14, in check_url_config
    return check_resolver(resolver)
  File "/root/anaconda3/lib/python3.10/site-packages/django/core/checks/urls.py", line 24, in check_resolver
    return check_method()
  File "/root/anaconda3/lib/python3.10/site-packages/django/urls/resolvers.py", line 494, in check
    for pattern in self.url_patterns:
  File "/root/anaconda3/lib/python3.10/site-packages/django/utils/functional.py", line 57, in __get__
    res = instance.__dict__[self.name] = self.func(instance)
  File "/root/anaconda3/lib/python3.10/site-packages/django/urls/resolvers.py", line 715, in url_patterns
    patterns = getattr(self.urlconf_module, "urlpatterns", self.urlconf_module)
  File "/root/anaconda3/lib/python3.10/site-packages/django/utils/functional.py", line 57, in __get__
    res = instance.__dict__[self.name] = self.func(instance)
  File "/root/anaconda3/lib/python3.10/site-packages/django/urls/resolvers.py", line 708, in urlconf_module
    return import_module(self.urlconf_name)
  File "/root/anaconda3/lib/python3.10/importlib/__init__.py", line 126, in import_module
    return _bootstrap._gcd_import(name[level:], package, level)
  File "<frozen importlib._bootstrap>", line 1050, in _gcd_import
  File "<frozen importlib._bootstrap>", line 1027, in _find_and_load
  File "<frozen importlib._bootstrap>", line 1006, in _find_and_load_unlocked
  File "<frozen importlib._bootstrap>", line 688, in _load_unlocked
  File "<frozen importlib._bootstrap_external>", line 883, in exec_module
  File "<frozen importlib._bootstrap>", line 241, in _call_with_frames_removed
  File "/home/kc/blancexchangeapi/blankexchange/urls.py", line 45, in <module>
    path('bank/',include(('core_app_root.user_services.bankmanagement.routers','core_app_root.user_services.bankmanagement'))),
  File "/root/anaconda3/lib/python3.10/site-packages/django/urls/conf.py", line 38, in include
    urlconf_module = import_module(urlconf_module)
  File "/root/anaconda3/lib/python3.10/importlib/__init__.py", line 126, in import_module
    return _bootstrap._gcd_import(name[level:], package, level)
  File "<frozen importlib._bootstrap>", line 1050, in _gcd_import
  File "<frozen importlib._bootstrap>", line 1027, in _find_and_load
  File "<frozen importlib._bootstrap>", line 1006, in _find_and_load_unlocked
  File "<frozen importlib._bootstrap>", line 688, in _load_unlocked
  File "<frozen importlib._bootstrap_external>", line 883, in exec_module
  File "<frozen importlib._bootstrap>", line 241, in _call_with_frames_removed
  File "/home/kc/blancexchangeapi/core_app_root/user_services/bankmanagement/routers.py", line 2, in <module>
    from core_app_root.user_services.bankmanagement.viewsets.bankmanagementviewset import BankManagementViewset,UserBankDetailsViewset
  File "/home/kc/blancexchangeapi/core_app_root/user_services/bankmanagement/viewsets/bankmanagementviewset.py", line 52
    'account_number': str(serializer.validated_data[]),
                          ^^^^^^^^^^^^^^^^^^^^^^^^^^^
SyntaxError: invalid syntax. Perhaps you forgot a comma?
Performing system checks...

System check identified no issues (0 silenced).
June 17, 2024 - 01:16:39
Django version 4.2.11, using settings 'blankexchange.settings'
Starting development server at http://192.81.210.127:1234/
Quit the server with CONTROL-C.

Performing system checks...

System check identified no issues (0 silenced).
June 17, 2024 - 01:16:47
Django version 4.2.11, using settings 'blankexchange.settings'
Starting development server at http://192.81.210.127:1234/
Quit the server with CONTROL-C.

Performing system checks...

System check identified no issues (0 silenced).
June 17, 2024 - 01:17:15
Django version 4.2.11, using settings 'blankexchange.settings'
Starting development server at http://192.81.210.127:1234/
Quit the server with CONTROL-C.

Performing system checks...

Exception in thread django-main-thread:
Traceback (most recent call last):
  File "/root/anaconda3/lib/python3.10/threading.py", line 1016, in _bootstrap_inner
    self.run()
  File "/root/anaconda3/lib/python3.10/threading.py", line 953, in run
    self._target(*self._args, **self._kwargs)
  File "/root/anaconda3/lib/python3.10/site-packages/django/utils/autoreload.py", line 64, in wrapper
    fn(*args, **kwargs)
  File "/root/anaconda3/lib/python3.10/site-packages/django/core/management/commands/runserver.py", line 133, in inner_run
    self.check(display_num_errors=True)
  File "/root/anaconda3/lib/python3.10/site-packages/django/core/management/base.py", line 485, in check
    all_issues = checks.run_checks(
  File "/root/anaconda3/lib/python3.10/site-packages/django/core/checks/registry.py", line 88, in run_checks
    new_errors = check(app_configs=app_configs, databases=databases)
  File "/root/anaconda3/lib/python3.10/site-packages/django/core/checks/urls.py", line 14, in check_url_config
    return check_resolver(resolver)
  File "/root/anaconda3/lib/python3.10/site-packages/django/core/checks/urls.py", line 24, in check_resolver
    return check_method()
  File "/root/anaconda3/lib/python3.10/site-packages/django/urls/resolvers.py", line 494, in check
    for pattern in self.url_patterns:
  File "/root/anaconda3/lib/python3.10/site-packages/django/utils/functional.py", line 57, in __get__
    res = instance.__dict__[self.name] = self.func(instance)
  File "/root/anaconda3/lib/python3.10/site-packages/django/urls/resolvers.py", line 715, in url_patterns
    patterns = getattr(self.urlconf_module, "urlpatterns", self.urlconf_module)
  File "/root/anaconda3/lib/python3.10/site-packages/django/utils/functional.py", line 57, in __get__
    res = instance.__dict__[self.name] = self.func(instance)
  File "/root/anaconda3/lib/python3.10/site-packages/django/urls/resolvers.py", line 708, in urlconf_module
    return import_module(self.urlconf_name)
  File "/root/anaconda3/lib/python3.10/importlib/__init__.py", line 126, in import_module
    return _bootstrap._gcd_import(name[level:], package, level)
  File "<frozen importlib._bootstrap>", line 1050, in _gcd_import
  File "<frozen importlib._bootstrap>", line 1027, in _find_and_load
  File "<frozen importlib._bootstrap>", line 1006, in _find_and_load_unlocked
  File "<frozen importlib._bootstrap>", line 688, in _load_unlocked
  File "<frozen importlib._bootstrap_external>", line 883, in exec_module
  File "<frozen importlib._bootstrap>", line 241, in _call_with_frames_removed
  File "/home/kc/blancexchangeapi/blankexchange/urls.py", line 45, in <module>
    path('bank/',include(('core_app_root.user_services.bankmanagement.routers','core_app_root.user_services.bankmanagement'))),
  File "/root/anaconda3/lib/python3.10/site-packages/django/urls/conf.py", line 38, in include
    urlconf_module = import_module(urlconf_module)
  File "/root/anaconda3/lib/python3.10/importlib/__init__.py", line 126, in import_module
    return _bootstrap._gcd_import(name[level:], package, level)
  File "<frozen importlib._bootstrap>", line 1050, in _gcd_import
  File "<frozen importlib._bootstrap>", line 1027, in _find_and_load
  File "<frozen importlib._bootstrap>", line 1006, in _find_and_load_unlocked
  File "<frozen importlib._bootstrap>", line 688, in _load_unlocked
  File "<frozen importlib._bootstrap_external>", line 883, in exec_module
  File "<frozen importlib._bootstrap>", line 241, in _call_with_frames_removed
  File "/home/kc/blancexchangeapi/core_app_root/user_services/bankmanagement/routers.py", line 2, in <module>
    from core_app_root.user_services.bankmanagement.viewsets.bankmanagementviewset import BankManagementViewset,UserBankDetailsViewset
  File "/home/kc/blancexchangeapi/core_app_root/user_services/bankmanagement/viewsets/bankmanagementviewset.py", line 53
    'bank_code': str(serializer.validated_data[])
                     ^^^^^^^^^^^^^^^^^^^^^^^^^^^
SyntaxError: invalid syntax. Perhaps you forgot a comma?
Performing system checks...

System check identified no issues (0 silenced).
June 17, 2024 - 01:17:22
Django version 4.2.11, using settings 'blankexchange.settings'
Starting development server at http://192.81.210.127:1234/
Quit the server with CONTROL-C.

Performing system checks...

System check identified no issues (0 silenced).
June 17, 2024 - 01:17:25
Django version 4.2.11, using settings 'blankexchange.settings'
Starting development server at http://192.81.210.127:1234/
Quit the server with CONTROL-C.

Performing system checks...

System check identified no issues (0 silenced).
June 17, 2024 - 01:17:43
Django version 4.2.11, using settings 'blankexchange.settings'
Starting development server at http://192.81.210.127:1234/
Quit the server with CONTROL-C.

Performing system checks...

System check identified no issues (0 silenced).
June 17, 2024 - 01:17:58
Django version 4.2.11, using settings 'blankexchange.settings'
Starting development server at http://192.81.210.127:1234/
Quit the server with CONTROL-C.

Performing system checks...

System check identified no issues (0 silenced).
June 17, 2024 - 01:18:04
Django version 4.2.11, using settings 'blankexchange.settings'
Starting development server at http://192.81.210.127:1234/
Quit the server with CONTROL-C.

Performing system checks...

System check identified no issues (0 silenced).
June 17, 2024 - 01:18:14
Django version 4.2.11, using settings 'blankexchange.settings'
Starting development server at http://192.81.210.127:1234/
Quit the server with CONTROL-C.

Performing system checks...

Exception in thread django-main-thread:
Traceback (most recent call last):
  File "/root/anaconda3/lib/python3.10/threading.py", line 1016, in _bootstrap_inner
    self.run()
  File "/root/anaconda3/lib/python3.10/threading.py", line 953, in run
    self._target(*self._args, **self._kwargs)
  File "/root/anaconda3/lib/python3.10/site-packages/django/utils/autoreload.py", line 64, in wrapper
    fn(*args, **kwargs)
  File "/root/anaconda3/lib/python3.10/site-packages/django/core/management/commands/runserver.py", line 133, in inner_run
    self.check(display_num_errors=True)
  File "/root/anaconda3/lib/python3.10/site-packages/django/core/management/base.py", line 485, in check
    all_issues = checks.run_checks(
  File "/root/anaconda3/lib/python3.10/site-packages/django/core/checks/registry.py", line 88, in run_checks
    new_errors = check(app_configs=app_configs, databases=databases)
  File "/root/anaconda3/lib/python3.10/site-packages/django/core/checks/urls.py", line 14, in check_url_config
    return check_resolver(resolver)
  File "/root/anaconda3/lib/python3.10/site-packages/django/core/checks/urls.py", line 24, in check_resolver
    return check_method()
  File "/root/anaconda3/lib/python3.10/site-packages/django/urls/resolvers.py", line 494, in check
    for pattern in self.url_patterns:
  File "/root/anaconda3/lib/python3.10/site-packages/django/utils/functional.py", line 57, in __get__
    res = instance.__dict__[self.name] = self.func(instance)
  File "/root/anaconda3/lib/python3.10/site-packages/django/urls/resolvers.py", line 715, in url_patterns
    patterns = getattr(self.urlconf_module, "urlpatterns", self.urlconf_module)
  File "/root/anaconda3/lib/python3.10/site-packages/django/utils/functional.py", line 57, in __get__
    res = instance.__dict__[self.name] = self.func(instance)
  File "/root/anaconda3/lib/python3.10/site-packages/django/urls/resolvers.py", line 708, in urlconf_module
    return import_module(self.urlconf_name)
  File "/root/anaconda3/lib/python3.10/importlib/__init__.py", line 126, in import_module
    return _bootstrap._gcd_import(name[level:], package, level)
  File "<frozen importlib._bootstrap>", line 1050, in _gcd_import
  File "<frozen importlib._bootstrap>", line 1027, in _find_and_load
  File "<frozen importlib._bootstrap>", line 1006, in _find_and_load_unlocked
  File "<frozen importlib._bootstrap>", line 688, in _load_unlocked
  File "<frozen importlib._bootstrap_external>", line 883, in exec_module
  File "<frozen importlib._bootstrap>", line 241, in _call_with_frames_removed
  File "/home/kc/blancexchangeapi/blankexchange/urls.py", line 45, in <module>
    path('bank/',include(('core_app_root.user_services.bankmanagement.routers','core_app_root.user_services.bankmanagement'))),
  File "/root/anaconda3/lib/python3.10/site-packages/django/urls/conf.py", line 38, in include
    urlconf_module = import_module(urlconf_module)
  File "/root/anaconda3/lib/python3.10/importlib/__init__.py", line 126, in import_module
    return _bootstrap._gcd_import(name[level:], package, level)
  File "<frozen importlib._bootstrap>", line 1050, in _gcd_import
  File "<frozen importlib._bootstrap>", line 1027, in _find_and_load
  File "<frozen importlib._bootstrap>", line 1006, in _find_and_load_unlocked
  File "<frozen importlib._bootstrap>", line 688, in _load_unlocked
  File "<frozen importlib._bootstrap_external>", line 883, in exec_module
  File "<frozen importlib._bootstrap>", line 241, in _call_with_frames_removed
  File "/home/kc/blancexchangeapi/core_app_root/user_services/bankmanagement/routers.py", line 2, in <module>
    from core_app_root.user_services.bankmanagement.viewsets.bankmanagementviewset import BankManagementViewset,UserBankDetailsViewset
  File "/home/kc/blancexchangeapi/core_app_root/user_services/bankmanagement/viewsets/bankmanagementviewset.py", line 77
    return Response({"status":False,"message":"bank name fetched successfully",""})
                                                                                ^
SyntaxError: ':' expected after dictionary key
Performing system checks...

Exception in thread django-main-thread:
Traceback (most recent call last):
  File "/root/anaconda3/lib/python3.10/threading.py", line 1016, in _bootstrap_inner
    self.run()
  File "/root/anaconda3/lib/python3.10/threading.py", line 953, in run
    self._target(*self._args, **self._kwargs)
  File "/root/anaconda3/lib/python3.10/site-packages/django/utils/autoreload.py", line 64, in wrapper
    fn(*args, **kwargs)
  File "/root/anaconda3/lib/python3.10/site-packages/django/core/management/commands/runserver.py", line 133, in inner_run
    self.check(display_num_errors=True)
  File "/root/anaconda3/lib/python3.10/site-packages/django/core/management/base.py", line 485, in check
    all_issues = checks.run_checks(
  File "/root/anaconda3/lib/python3.10/site-packages/django/core/checks/registry.py", line 88, in run_checks
    new_errors = check(app_configs=app_configs, databases=databases)
  File "/root/anaconda3/lib/python3.10/site-packages/django/core/checks/urls.py", line 14, in check_url_config
    return check_resolver(resolver)
  File "/root/anaconda3/lib/python3.10/site-packages/django/core/checks/urls.py", line 24, in check_resolver
    return check_method()
  File "/root/anaconda3/lib/python3.10/site-packages/django/urls/resolvers.py", line 494, in check
    for pattern in self.url_patterns:
  File "/root/anaconda3/lib/python3.10/site-packages/django/utils/functional.py", line 57, in __get__
    res = instance.__dict__[self.name] = self.func(instance)
  File "/root/anaconda3/lib/python3.10/site-packages/django/urls/resolvers.py", line 715, in url_patterns
    patterns = getattr(self.urlconf_module, "urlpatterns", self.urlconf_module)
  File "/root/anaconda3/lib/python3.10/site-packages/django/utils/functional.py", line 57, in __get__
    res = instance.__dict__[self.name] = self.func(instance)
  File "/root/anaconda3/lib/python3.10/site-packages/django/urls/resolvers.py", line 708, in urlconf_module
    return import_module(self.urlconf_name)
  File "/root/anaconda3/lib/python3.10/importlib/__init__.py", line 126, in import_module
    return _bootstrap._gcd_import(name[level:], package, level)
  File "<frozen importlib._bootstrap>", line 1050, in _gcd_import
  File "<frozen importlib._bootstrap>", line 1027, in _find_and_load
  File "<frozen importlib._bootstrap>", line 1006, in _find_and_load_unlocked
  File "<frozen importlib._bootstrap>", line 688, in _load_unlocked
  File "<frozen importlib._bootstrap_external>", line 883, in exec_module
  File "<frozen importlib._bootstrap>", line 241, in _call_with_frames_removed
  File "/home/kc/blancexchangeapi/blankexchange/urls.py", line 45, in <module>
    path('bank/',include(('core_app_root.user_services.bankmanagement.routers','core_app_root.user_services.bankmanagement'))),
  File "/root/anaconda3/lib/python3.10/site-packages/django/urls/conf.py", line 38, in include
    urlconf_module = import_module(urlconf_module)
  File "/root/anaconda3/lib/python3.10/importlib/__init__.py", line 126, in import_module
    return _bootstrap._gcd_import(name[level:], package, level)
  File "<frozen importlib._bootstrap>", line 1050, in _gcd_import
  File "<frozen importlib._bootstrap>", line 1027, in _find_and_load
  File "<frozen importlib._bootstrap>", line 1006, in _find_and_load_unlocked
  File "<frozen importlib._bootstrap>", line 688, in _load_unlocked
  File "<frozen importlib._bootstrap_external>", line 883, in exec_module
  File "<frozen importlib._bootstrap>", line 241, in _call_with_frames_removed
  File "/home/kc/blancexchangeapi/core_app_root/user_services/bankmanagement/routers.py", line 2, in <module>
    from core_app_root.user_services.bankmanagement.viewsets.bankmanagementviewset import BankManagementViewset,UserBankDetailsViewset
  File "/home/kc/blancexchangeapi/core_app_root/user_services/bankmanagement/viewsets/bankmanagementviewset.py", line 77
    return Response({"status":False,"message":"bank name fetched successfully","data"})
                                                                                    ^
SyntaxError: ':' expected after dictionary key
Performing system checks...

Exception in thread django-main-thread:
Traceback (most recent call last):
  File "/root/anaconda3/lib/python3.10/threading.py", line 1016, in _bootstrap_inner
    self.run()
  File "/root/anaconda3/lib/python3.10/threading.py", line 953, in run
    self._target(*self._args, **self._kwargs)
  File "/root/anaconda3/lib/python3.10/site-packages/django/utils/autoreload.py", line 64, in wrapper
    fn(*args, **kwargs)
  File "/root/anaconda3/lib/python3.10/site-packages/django/core/management/commands/runserver.py", line 133, in inner_run
    self.check(display_num_errors=True)
  File "/root/anaconda3/lib/python3.10/site-packages/django/core/management/base.py", line 485, in check
    all_issues = checks.run_checks(
  File "/root/anaconda3/lib/python3.10/site-packages/django/core/checks/registry.py", line 88, in run_checks
    new_errors = check(app_configs=app_configs, databases=databases)
  File "/root/anaconda3/lib/python3.10/site-packages/django/core/checks/urls.py", line 14, in check_url_config
    return check_resolver(resolver)
  File "/root/anaconda3/lib/python3.10/site-packages/django/core/checks/urls.py", line 24, in check_resolver
    return check_method()
  File "/root/anaconda3/lib/python3.10/site-packages/django/urls/resolvers.py", line 494, in check
    for pattern in self.url_patterns:
  File "/root/anaconda3/lib/python3.10/site-packages/django/utils/functional.py", line 57, in __get__
    res = instance.__dict__[self.name] = self.func(instance)
  File "/root/anaconda3/lib/python3.10/site-packages/django/urls/resolvers.py", line 715, in url_patterns
    patterns = getattr(self.urlconf_module, "urlpatterns", self.urlconf_module)
  File "/root/anaconda3/lib/python3.10/site-packages/django/utils/functional.py", line 57, in __get__
    res = instance.__dict__[self.name] = self.func(instance)
  File "/root/anaconda3/lib/python3.10/site-packages/django/urls/resolvers.py", line 708, in urlconf_module
    return import_module(self.urlconf_name)
  File "/root/anaconda3/lib/python3.10/importlib/__init__.py", line 126, in import_module
    return _bootstrap._gcd_import(name[level:], package, level)
  File "<frozen importlib._bootstrap>", line 1050, in _gcd_import
  File "<frozen importlib._bootstrap>", line 1027, in _find_and_load
  File "<frozen importlib._bootstrap>", line 1006, in _find_and_load_unlocked
  File "<frozen importlib._bootstrap>", line 688, in _load_unlocked
  File "<frozen importlib._bootstrap_external>", line 883, in exec_module
  File "<frozen importlib._bootstrap>", line 241, in _call_with_frames_removed
  File "/home/kc/blancexchangeapi/blankexchange/urls.py", line 45, in <module>
    path('bank/',include(('core_app_root.user_services.bankmanagement.routers','core_app_root.user_services.bankmanagement'))),
  File "/root/anaconda3/lib/python3.10/site-packages/django/urls/conf.py", line 38, in include
    urlconf_module = import_module(urlconf_module)
  File "/root/anaconda3/lib/python3.10/importlib/__init__.py", line 126, in import_module
    return _bootstrap._gcd_import(name[level:], package, level)
  File "<frozen importlib._bootstrap>", line 1050, in _gcd_import
  File "<frozen importlib._bootstrap>", line 1027, in _find_and_load
  File "<frozen importlib._bootstrap>", line 1006, in _find_and_load_unlocked
  File "<frozen importlib._bootstrap>", line 688, in _load_unlocked
  File "<frozen importlib._bootstrap_external>", line 883, in exec_module
  File "<frozen importlib._bootstrap>", line 241, in _call_with_frames_removed
  File "/home/kc/blancexchangeapi/core_app_root/user_services/bankmanagement/routers.py", line 2, in <module>
    from core_app_root.user_services.bankmanagement.viewsets.bankmanagementviewset import BankManagementViewset,UserBankDetailsViewset
  File "/home/kc/blancexchangeapi/core_app_root/user_services/bankmanagement/viewsets/bankmanagementviewset.py", line 77
    return Response({"status":False,"message":"bank name fetched successfully","data":})
                                                                                     ^
SyntaxError: expression expected after dictionary key and ':'
Performing system checks...

System check identified no issues (0 silenced).
June 17, 2024 - 01:18:40
Django version 4.2.11, using settings 'blankexchange.settings'
Starting development server at http://192.81.210.127:1234/
Quit the server with CONTROL-C.

Performing system checks...

System check identified no issues (0 silenced).
June 17, 2024 - 01:19:03
Django version 4.2.11, using settings 'blankexchange.settings'
Starting development server at http://192.81.210.127:1234/
Quit the server with CONTROL-C.

Performing system checks...

System check identified no issues (0 silenced).
June 17, 2024 - 01:19:12
Django version 4.2.11, using settings 'blankexchange.settings'
Starting development server at http://192.81.210.127:1234/
Quit the server with CONTROL-C.

Performing system checks...

System check identified no issues (0 silenced).
June 17, 2024 - 01:19:16
Django version 4.2.11, using settings 'blankexchange.settings'
Starting development server at http://192.81.210.127:1234/
Quit the server with CONTROL-C.

Performing system checks...

System check identified no issues (0 silenced).
June 17, 2024 - 01:19:21
Django version 4.2.11, using settings 'blankexchange.settings'
Starting development server at http://192.81.210.127:1234/
Quit the server with CONTROL-C.

Performing system checks...

System check identified no issues (0 silenced).
June 17, 2024 - 01:19:28
Django version 4.2.11, using settings 'blankexchange.settings'
Starting development server at http://192.81.210.127:1234/
Quit the server with CONTROL-C.

Performing system checks...

System check identified no issues (0 silenced).
June 17, 2024 - 01:19:32
Django version 4.2.11, using settings 'blankexchange.settings'
Starting development server at http://192.81.210.127:1234/
Quit the server with CONTROL-C.

Performing system checks...

System check identified no issues (0 silenced).
June 17, 2024 - 01:19:35
Django version 4.2.11, using settings 'blankexchange.settings'
Starting development server at http://192.81.210.127:1234/
Quit the server with CONTROL-C.

Performing system checks...

System check identified no issues (0 silenced).
June 17, 2024 - 01:23:15
Django version 4.2.11, using settings 'blankexchange.settings'
Starting development server at http://192.81.210.127:1234/
Quit the server with CONTROL-C.

Performing system checks...

System check identified no issues (0 silenced).
June 17, 2024 - 01:23:19
Django version 4.2.11, using settings 'blankexchange.settings'
Starting development server at http://192.81.210.127:1234/
Quit the server with CONTROL-C.

Performing system checks...

System check identified no issues (0 silenced).
June 17, 2024 - 01:23:22
Django version 4.2.11, using settings 'blankexchange.settings'
Starting development server at http://192.81.210.127:1234/
Quit the server with CONTROL-C.

Performing system checks...

System check identified no issues (0 silenced).
June 17, 2024 - 01:24:58
Django version 4.2.11, using settings 'blankexchange.settings'
Starting development server at http://192.81.210.127:1234/
Quit the server with CONTROL-C.

Performing system checks...

System check identified no issues (0 silenced).
June 17, 2024 - 01:25:05
Django version 4.2.11, using settings 'blankexchange.settings'
Starting development server at http://192.81.210.127:1234/
Quit the server with CONTROL-C.

Performing system checks...

Exception in thread django-main-thread:
Traceback (most recent call last):
  File "/root/anaconda3/lib/python3.10/threading.py", line 1016, in _bootstrap_inner
    self.run()
  File "/root/anaconda3/lib/python3.10/threading.py", line 953, in run
    self._target(*self._args, **self._kwargs)
  File "/root/anaconda3/lib/python3.10/site-packages/django/utils/autoreload.py", line 64, in wrapper
    fn(*args, **kwargs)
  File "/root/anaconda3/lib/python3.10/site-packages/django/core/management/commands/runserver.py", line 133, in inner_run
    self.check(display_num_errors=True)
  File "/root/anaconda3/lib/python3.10/site-packages/django/core/management/base.py", line 485, in check
    all_issues = checks.run_checks(
  File "/root/anaconda3/lib/python3.10/site-packages/django/core/checks/registry.py", line 88, in run_checks
    new_errors = check(app_configs=app_configs, databases=databases)
  File "/root/anaconda3/lib/python3.10/site-packages/django/core/checks/urls.py", line 14, in check_url_config
    return check_resolver(resolver)
  File "/root/anaconda3/lib/python3.10/site-packages/django/core/checks/urls.py", line 24, in check_resolver
    return check_method()
  File "/root/anaconda3/lib/python3.10/site-packages/django/urls/resolvers.py", line 494, in check
    for pattern in self.url_patterns:
  File "/root/anaconda3/lib/python3.10/site-packages/django/utils/functional.py", line 57, in __get__
    res = instance.__dict__[self.name] = self.func(instance)
  File "/root/anaconda3/lib/python3.10/site-packages/django/urls/resolvers.py", line 715, in url_patterns
    patterns = getattr(self.urlconf_module, "urlpatterns", self.urlconf_module)
  File "/root/anaconda3/lib/python3.10/site-packages/django/utils/functional.py", line 57, in __get__
    res = instance.__dict__[self.name] = self.func(instance)
  File "/root/anaconda3/lib/python3.10/site-packages/django/urls/resolvers.py", line 708, in urlconf_module
    return import_module(self.urlconf_name)
  File "/root/anaconda3/lib/python3.10/importlib/__init__.py", line 126, in import_module
    return _bootstrap._gcd_import(name[level:], package, level)
  File "<frozen importlib._bootstrap>", line 1050, in _gcd_import
  File "<frozen importlib._bootstrap>", line 1027, in _find_and_load
  File "<frozen importlib._bootstrap>", line 1006, in _find_and_load_unlocked
  File "<frozen importlib._bootstrap>", line 688, in _load_unlocked
  File "<frozen importlib._bootstrap_external>", line 883, in exec_module
  File "<frozen importlib._bootstrap>", line 241, in _call_with_frames_removed
  File "/home/kc/blancexchangeapi/blankexchange/urls.py", line 45, in <module>
    path('bank/',include(('core_app_root.user_services.bankmanagement.routers','core_app_root.user_services.bankmanagement'))),
  File "/root/anaconda3/lib/python3.10/site-packages/django/urls/conf.py", line 38, in include
    urlconf_module = import_module(urlconf_module)
  File "/root/anaconda3/lib/python3.10/importlib/__init__.py", line 126, in import_module
    return _bootstrap._gcd_import(name[level:], package, level)
  File "<frozen importlib._bootstrap>", line 1050, in _gcd_import
  File "<frozen importlib._bootstrap>", line 1027, in _find_and_load
  File "<frozen importlib._bootstrap>", line 1006, in _find_and_load_unlocked
  File "<frozen importlib._bootstrap>", line 688, in _load_unlocked
  File "<frozen importlib._bootstrap_external>", line 883, in exec_module
  File "<frozen importlib._bootstrap>", line 241, in _call_with_frames_removed
  File "/home/kc/blancexchangeapi/core_app_root/user_services/bankmanagement/routers.py", line 2, in <module>
    from core_app_root.user_services.bankmanagement.viewsets.bankmanagementviewset import BankManagementViewset,UserBankDetailsViewset
  File "/home/kc/blancexchangeapi/core_app_root/user_services/bankmanagement/viewsets/bankmanagementviewset.py", line 80
    return Response({"status":False,"message":"bank name fetched successfully")
                                                                              ^
SyntaxError: closing parenthesis ')' does not match opening parenthesis '{'
Performing system checks...

System check identified no issues (0 silenced).
June 17, 2024 - 01:25:57
Django version 4.2.11, using settings 'blankexchange.settings'
Starting development server at http://192.81.210.127:1234/
Quit the server with CONTROL-C.

Performing system checks...

System check identified no issues (0 silenced).
June 17, 2024 - 01:26:00
Django version 4.2.11, using settings 'blankexchange.settings'
Starting development server at http://192.81.210.127:1234/
Quit the server with CONTROL-C.

Performing system checks...

Exception in thread django-main-thread:
Traceback (most recent call last):
  File "/root/anaconda3/lib/python3.10/threading.py", line 1016, in _bootstrap_inner
    self.run()
  File "/root/anaconda3/lib/python3.10/threading.py", line 953, in run
    self._target(*self._args, **self._kwargs)
  File "/root/anaconda3/lib/python3.10/site-packages/django/utils/autoreload.py", line 64, in wrapper
    fn(*args, **kwargs)
  File "/root/anaconda3/lib/python3.10/site-packages/django/core/management/commands/runserver.py", line 133, in inner_run
    self.check(display_num_errors=True)
  File "/root/anaconda3/lib/python3.10/site-packages/django/core/management/base.py", line 485, in check
    all_issues = checks.run_checks(
  File "/root/anaconda3/lib/python3.10/site-packages/django/core/checks/registry.py", line 88, in run_checks
    new_errors = check(app_configs=app_configs, databases=databases)
  File "/root/anaconda3/lib/python3.10/site-packages/django/core/checks/urls.py", line 14, in check_url_config
    return check_resolver(resolver)
  File "/root/anaconda3/lib/python3.10/site-packages/django/core/checks/urls.py", line 24, in check_resolver
    return check_method()
  File "/root/anaconda3/lib/python3.10/site-packages/django/urls/resolvers.py", line 494, in check
    for pattern in self.url_patterns:
  File "/root/anaconda3/lib/python3.10/site-packages/django/utils/functional.py", line 57, in __get__
    res = instance.__dict__[self.name] = self.func(instance)
  File "/root/anaconda3/lib/python3.10/site-packages/django/urls/resolvers.py", line 715, in url_patterns
    patterns = getattr(self.urlconf_module, "urlpatterns", self.urlconf_module)
  File "/root/anaconda3/lib/python3.10/site-packages/django/utils/functional.py", line 57, in __get__
    res = instance.__dict__[self.name] = self.func(instance)
  File "/root/anaconda3/lib/python3.10/site-packages/django/urls/resolvers.py", line 708, in urlconf_module
    return import_module(self.urlconf_name)
  File "/root/anaconda3/lib/python3.10/importlib/__init__.py", line 126, in import_module
    return _bootstrap._gcd_import(name[level:], package, level)
  File "<frozen importlib._bootstrap>", line 1050, in _gcd_import
  File "<frozen importlib._bootstrap>", line 1027, in _find_and_load
  File "<frozen importlib._bootstrap>", line 1006, in _find_and_load_unlocked
  File "<frozen importlib._bootstrap>", line 688, in _load_unlocked
  File "<frozen importlib._bootstrap_external>", line 883, in exec_module
  File "<frozen importlib._bootstrap>", line 241, in _call_with_frames_removed
  File "/home/kc/blancexchangeapi/blankexchange/urls.py", line 45, in <module>
    path('bank/',include(('core_app_root.user_services.bankmanagement.routers','core_app_root.user_services.bankmanagement'))),
  File "/root/anaconda3/lib/python3.10/site-packages/django/urls/conf.py", line 38, in include
    urlconf_module = import_module(urlconf_module)
  File "/root/anaconda3/lib/python3.10/importlib/__init__.py", line 126, in import_module
    return _bootstrap._gcd_import(name[level:], package, level)
  File "<frozen importlib._bootstrap>", line 1050, in _gcd_import
  File "<frozen importlib._bootstrap>", line 1027, in _find_and_load
  File "<frozen importlib._bootstrap>", line 1006, in _find_and_load_unlocked
  File "<frozen importlib._bootstrap>", line 688, in _load_unlocked
  File "<frozen importlib._bootstrap_external>", line 883, in exec_module
  File "<frozen importlib._bootstrap>", line 241, in _call_with_frames_removed
  File "/home/kc/blancexchangeapi/core_app_root/user_services/bankmanagement/routers.py", line 2, in <module>
    from core_app_root.user_services.bankmanagement.viewsets.bankmanagementviewset import BankManagementViewset,UserBankDetailsViewset
  File "/home/kc/blancexchangeapi/core_app_root/user_services/bankmanagement/viewsets/bankmanagementviewset.py", line 80
    return Response({"status":False,"message":"bank name fetched successfully")
                                                                              ^
SyntaxError: closing parenthesis ')' does not match opening parenthesis '{'
Performing system checks...

Exception in thread django-main-thread:
Traceback (most recent call last):
  File "/root/anaconda3/lib/python3.10/threading.py", line 1016, in _bootstrap_inner
    self.run()
  File "/root/anaconda3/lib/python3.10/threading.py", line 953, in run
    self._target(*self._args, **self._kwargs)
  File "/root/anaconda3/lib/python3.10/site-packages/django/utils/autoreload.py", line 64, in wrapper
    fn(*args, **kwargs)
  File "/root/anaconda3/lib/python3.10/site-packages/django/core/management/commands/runserver.py", line 133, in inner_run
    self.check(display_num_errors=True)
  File "/root/anaconda3/lib/python3.10/site-packages/django/core/management/base.py", line 485, in check
    all_issues = checks.run_checks(
  File "/root/anaconda3/lib/python3.10/site-packages/django/core/checks/registry.py", line 88, in run_checks
    new_errors = check(app_configs=app_configs, databases=databases)
  File "/root/anaconda3/lib/python3.10/site-packages/django/core/checks/urls.py", line 14, in check_url_config
    return check_resolver(resolver)
  File "/root/anaconda3/lib/python3.10/site-packages/django/core/checks/urls.py", line 24, in check_resolver
    return check_method()
  File "/root/anaconda3/lib/python3.10/site-packages/django/urls/resolvers.py", line 494, in check
    for pattern in self.url_patterns:
  File "/root/anaconda3/lib/python3.10/site-packages/django/utils/functional.py", line 57, in __get__
    res = instance.__dict__[self.name] = self.func(instance)
  File "/root/anaconda3/lib/python3.10/site-packages/django/urls/resolvers.py", line 715, in url_patterns
    patterns = getattr(self.urlconf_module, "urlpatterns", self.urlconf_module)
  File "/root/anaconda3/lib/python3.10/site-packages/django/utils/functional.py", line 57, in __get__
    res = instance.__dict__[self.name] = self.func(instance)
  File "/root/anaconda3/lib/python3.10/site-packages/django/urls/resolvers.py", line 708, in urlconf_module
    return import_module(self.urlconf_name)
  File "/root/anaconda3/lib/python3.10/importlib/__init__.py", line 126, in import_module
    return _bootstrap._gcd_import(name[level:], package, level)
  File "<frozen importlib._bootstrap>", line 1050, in _gcd_import
  File "<frozen importlib._bootstrap>", line 1027, in _find_and_load
  File "<frozen importlib._bootstrap>", line 1006, in _find_and_load_unlocked
  File "<frozen importlib._bootstrap>", line 688, in _load_unlocked
  File "<frozen importlib._bootstrap_external>", line 883, in exec_module
  File "<frozen importlib._bootstrap>", line 241, in _call_with_frames_removed
  File "/home/kc/blancexchangeapi/blankexchange/urls.py", line 45, in <module>
    path('bank/',include(('core_app_root.user_services.bankmanagement.routers','core_app_root.user_services.bankmanagement'))),
  File "/root/anaconda3/lib/python3.10/site-packages/django/urls/conf.py", line 38, in include
    urlconf_module = import_module(urlconf_module)
  File "/root/anaconda3/lib/python3.10/importlib/__init__.py", line 126, in import_module
    return _bootstrap._gcd_import(name[level:], package, level)
  File "<frozen importlib._bootstrap>", line 1050, in _gcd_import
  File "<frozen importlib._bootstrap>", line 1027, in _find_and_load
  File "<frozen importlib._bootstrap>", line 1006, in _find_and_load_unlocked
  File "<frozen importlib._bootstrap>", line 688, in _load_unlocked
  File "<frozen importlib._bootstrap_external>", line 883, in exec_module
  File "<frozen importlib._bootstrap>", line 241, in _call_with_frames_removed
  File "/home/kc/blancexchangeapi/core_app_root/user_services/bankmanagement/routers.py", line 2, in <module>
    from core_app_root.user_services.bankmanagement.viewsets.bankmanagementviewset import BankManagementViewset,UserBankDetailsViewset
  File "/home/kc/blancexchangeapi/core_app_root/user_services/bankmanagement/viewsets/bankmanagementviewset.py", line 80
    return Response({"status":False,"message":"bank name fetched successfully")
                                                                              ^
SyntaxError: closing parenthesis ')' does not match opening parenthesis '{'
Performing system checks...

Exception in thread django-main-thread:
Traceback (most recent call last):
  File "/root/anaconda3/lib/python3.10/threading.py", line 1016, in _bootstrap_inner
    self.run()
  File "/root/anaconda3/lib/python3.10/threading.py", line 953, in run
    self._target(*self._args, **self._kwargs)
  File "/root/anaconda3/lib/python3.10/site-packages/django/utils/autoreload.py", line 64, in wrapper
    fn(*args, **kwargs)
  File "/root/anaconda3/lib/python3.10/site-packages/django/core/management/commands/runserver.py", line 133, in inner_run
    self.check(display_num_errors=True)
  File "/root/anaconda3/lib/python3.10/site-packages/django/core/management/base.py", line 485, in check
    all_issues = checks.run_checks(
  File "/root/anaconda3/lib/python3.10/site-packages/django/core/checks/registry.py", line 88, in run_checks
    new_errors = check(app_configs=app_configs, databases=databases)
  File "/root/anaconda3/lib/python3.10/site-packages/django/core/checks/urls.py", line 14, in check_url_config
    return check_resolver(resolver)
  File "/root/anaconda3/lib/python3.10/site-packages/django/core/checks/urls.py", line 24, in check_resolver
    return check_method()
  File "/root/anaconda3/lib/python3.10/site-packages/django/urls/resolvers.py", line 494, in check
    for pattern in self.url_patterns:
  File "/root/anaconda3/lib/python3.10/site-packages/django/utils/functional.py", line 57, in __get__
    res = instance.__dict__[self.name] = self.func(instance)
  File "/root/anaconda3/lib/python3.10/site-packages/django/urls/resolvers.py", line 715, in url_patterns
    patterns = getattr(self.urlconf_module, "urlpatterns", self.urlconf_module)
  File "/root/anaconda3/lib/python3.10/site-packages/django/utils/functional.py", line 57, in __get__
    res = instance.__dict__[self.name] = self.func(instance)
  File "/root/anaconda3/lib/python3.10/site-packages/django/urls/resolvers.py", line 708, in urlconf_module
    return import_module(self.urlconf_name)
  File "/root/anaconda3/lib/python3.10/importlib/__init__.py", line 126, in import_module
    return _bootstrap._gcd_import(name[level:], package, level)
  File "<frozen importlib._bootstrap>", line 1050, in _gcd_import
  File "<frozen importlib._bootstrap>", line 1027, in _find_and_load
  File "<frozen importlib._bootstrap>", line 1006, in _find_and_load_unlocked
  File "<frozen importlib._bootstrap>", line 688, in _load_unlocked
  File "<frozen importlib._bootstrap_external>", line 883, in exec_module
  File "<frozen importlib._bootstrap>", line 241, in _call_with_frames_removed
  File "/home/kc/blancexchangeapi/blankexchange/urls.py", line 45, in <module>
    path('bank/',include(('core_app_root.user_services.bankmanagement.routers','core_app_root.user_services.bankmanagement'))),
  File "/root/anaconda3/lib/python3.10/site-packages/django/urls/conf.py", line 38, in include
    urlconf_module = import_module(urlconf_module)
  File "/root/anaconda3/lib/python3.10/importlib/__init__.py", line 126, in import_module
    return _bootstrap._gcd_import(name[level:], package, level)
  File "<frozen importlib._bootstrap>", line 1050, in _gcd_import
  File "<frozen importlib._bootstrap>", line 1027, in _find_and_load
  File "<frozen importlib._bootstrap>", line 1006, in _find_and_load_unlocked
  File "<frozen importlib._bootstrap>", line 688, in _load_unlocked
  File "<frozen importlib._bootstrap_external>", line 883, in exec_module
  File "<frozen importlib._bootstrap>", line 241, in _call_with_frames_removed
  File "/home/kc/blancexchangeapi/core_app_root/user_services/bankmanagement/routers.py", line 2, in <module>
    from core_app_root.user_services.bankmanagement.viewsets.bankmanagementviewset import BankManagementViewset,UserBankDetailsViewset
  File "/home/kc/blancexchangeapi/core_app_root/user_services/bankmanagement/viewsets/bankmanagementviewset.py", line 35
    serializer=self.serializer_class(data=request.data)
    ^
IndentationError: expected an indented block after function definition on line 34
Performing system checks...

Exception in thread django-main-thread:
Traceback (most recent call last):
  File "/root/anaconda3/lib/python3.10/threading.py", line 1016, in _bootstrap_inner
    self.run()
  File "/root/anaconda3/lib/python3.10/threading.py", line 953, in run
    self._target(*self._args, **self._kwargs)
  File "/root/anaconda3/lib/python3.10/site-packages/django/utils/autoreload.py", line 64, in wrapper
    fn(*args, **kwargs)
  File "/root/anaconda3/lib/python3.10/site-packages/django/core/management/commands/runserver.py", line 133, in inner_run
    self.check(display_num_errors=True)
  File "/root/anaconda3/lib/python3.10/site-packages/django/core/management/base.py", line 485, in check
    all_issues = checks.run_checks(
  File "/root/anaconda3/lib/python3.10/site-packages/django/core/checks/registry.py", line 88, in run_checks
    new_errors = check(app_configs=app_configs, databases=databases)
  File "/root/anaconda3/lib/python3.10/site-packages/django/core/checks/urls.py", line 14, in check_url_config
    return check_resolver(resolver)
  File "/root/anaconda3/lib/python3.10/site-packages/django/core/checks/urls.py", line 24, in check_resolver
    return check_method()
  File "/root/anaconda3/lib/python3.10/site-packages/django/urls/resolvers.py", line 494, in check
    for pattern in self.url_patterns:
  File "/root/anaconda3/lib/python3.10/site-packages/django/utils/functional.py", line 57, in __get__
    res = instance.__dict__[self.name] = self.func(instance)
  File "/root/anaconda3/lib/python3.10/site-packages/django/urls/resolvers.py", line 715, in url_patterns
    patterns = getattr(self.urlconf_module, "urlpatterns", self.urlconf_module)
  File "/root/anaconda3/lib/python3.10/site-packages/django/utils/functional.py", line 57, in __get__
    res = instance.__dict__[self.name] = self.func(instance)
  File "/root/anaconda3/lib/python3.10/site-packages/django/urls/resolvers.py", line 708, in urlconf_module
    return import_module(self.urlconf_name)
  File "/root/anaconda3/lib/python3.10/importlib/__init__.py", line 126, in import_module
    return _bootstrap._gcd_import(name[level:], package, level)
  File "<frozen importlib._bootstrap>", line 1050, in _gcd_import
  File "<frozen importlib._bootstrap>", line 1027, in _find_and_load
  File "<frozen importlib._bootstrap>", line 1006, in _find_and_load_unlocked
  File "<frozen importlib._bootstrap>", line 688, in _load_unlocked
  File "<frozen importlib._bootstrap_external>", line 883, in exec_module
  File "<frozen importlib._bootstrap>", line 241, in _call_with_frames_removed
  File "/home/kc/blancexchangeapi/blankexchange/urls.py", line 45, in <module>
    path('bank/',include(('core_app_root.user_services.bankmanagement.routers','core_app_root.user_services.bankmanagement'))),
  File "/root/anaconda3/lib/python3.10/site-packages/django/urls/conf.py", line 38, in include
    urlconf_module = import_module(urlconf_module)
  File "/root/anaconda3/lib/python3.10/importlib/__init__.py", line 126, in import_module
    return _bootstrap._gcd_import(name[level:], package, level)
  File "<frozen importlib._bootstrap>", line 1050, in _gcd_import
  File "<frozen importlib._bootstrap>", line 1027, in _find_and_load
  File "<frozen importlib._bootstrap>", line 1006, in _find_and_load_unlocked
  File "<frozen importlib._bootstrap>", line 688, in _load_unlocked
  File "<frozen importlib._bootstrap_external>", line 883, in exec_module
  File "<frozen importlib._bootstrap>", line 241, in _call_with_frames_removed
  File "/home/kc/blancexchangeapi/core_app_root/user_services/bankmanagement/routers.py", line 2, in <module>
    from core_app_root.user_services.bankmanagement.viewsets.bankmanagementviewset import BankManagementViewset,UserBankDetailsViewset
  File "/home/kc/blancexchangeapi/core_app_root/user_services/bankmanagement/viewsets/bankmanagementviewset.py", line 80
    return Response({"status":False,"message":"bank name fetched successfully")
                                                                              ^
SyntaxError: closing parenthesis ')' does not match opening parenthesis '{'
Performing system checks...

System check identified no issues (0 silenced).
June 17, 2024 - 01:31:25
Django version 4.2.11, using settings 'blankexchange.settings'
Starting development server at http://192.81.210.127:1234/
Quit the server with CONTROL-C.

Performing system checks...

Exception in thread django-main-thread:
Traceback (most recent call last):
  File "/root/anaconda3/lib/python3.10/threading.py", line 1016, in _bootstrap_inner
    self.run()
  File "/root/anaconda3/lib/python3.10/threading.py", line 953, in run
    self._target(*self._args, **self._kwargs)
  File "/root/anaconda3/lib/python3.10/site-packages/django/utils/autoreload.py", line 64, in wrapper
    fn(*args, **kwargs)
  File "/root/anaconda3/lib/python3.10/site-packages/django/core/management/commands/runserver.py", line 133, in inner_run
    self.check(display_num_errors=True)
  File "/root/anaconda3/lib/python3.10/site-packages/django/core/management/base.py", line 485, in check
    all_issues = checks.run_checks(
  File "/root/anaconda3/lib/python3.10/site-packages/django/core/checks/registry.py", line 88, in run_checks
    new_errors = check(app_configs=app_configs, databases=databases)
  File "/root/anaconda3/lib/python3.10/site-packages/django/core/checks/urls.py", line 14, in check_url_config
    return check_resolver(resolver)
  File "/root/anaconda3/lib/python3.10/site-packages/django/core/checks/urls.py", line 24, in check_resolver
    return check_method()
  File "/root/anaconda3/lib/python3.10/site-packages/django/urls/resolvers.py", line 494, in check
    for pattern in self.url_patterns:
  File "/root/anaconda3/lib/python3.10/site-packages/django/utils/functional.py", line 57, in __get__
    res = instance.__dict__[self.name] = self.func(instance)
  File "/root/anaconda3/lib/python3.10/site-packages/django/urls/resolvers.py", line 715, in url_patterns
    patterns = getattr(self.urlconf_module, "urlpatterns", self.urlconf_module)
  File "/root/anaconda3/lib/python3.10/site-packages/django/utils/functional.py", line 57, in __get__
    res = instance.__dict__[self.name] = self.func(instance)
  File "/root/anaconda3/lib/python3.10/site-packages/django/urls/resolvers.py", line 708, in urlconf_module
    return import_module(self.urlconf_name)
  File "/root/anaconda3/lib/python3.10/importlib/__init__.py", line 126, in import_module
    return _bootstrap._gcd_import(name[level:], package, level)
  File "<frozen importlib._bootstrap>", line 1050, in _gcd_import
  File "<frozen importlib._bootstrap>", line 1027, in _find_and_load
  File "<frozen importlib._bootstrap>", line 1006, in _find_and_load_unlocked
  File "<frozen importlib._bootstrap>", line 688, in _load_unlocked
  File "<frozen importlib._bootstrap_external>", line 883, in exec_module
  File "<frozen importlib._bootstrap>", line 241, in _call_with_frames_removed
  File "/home/kc/blancexchangeapi/blankexchange/urls.py", line 45, in <module>
    path('bank/',include(('core_app_root.user_services.bankmanagement.routers','core_app_root.user_services.bankmanagement'))),
  File "/root/anaconda3/lib/python3.10/site-packages/django/urls/conf.py", line 38, in include
    urlconf_module = import_module(urlconf_module)
  File "/root/anaconda3/lib/python3.10/importlib/__init__.py", line 126, in import_module
    return _bootstrap._gcd_import(name[level:], package, level)
  File "<frozen importlib._bootstrap>", line 1050, in _gcd_import
  File "<frozen importlib._bootstrap>", line 1027, in _find_and_load
  File "<frozen importlib._bootstrap>", line 1006, in _find_and_load_unlocked
  File "<frozen importlib._bootstrap>", line 688, in _load_unlocked
  File "<frozen importlib._bootstrap_external>", line 883, in exec_module
  File "<frozen importlib._bootstrap>", line 241, in _call_with_frames_removed
  File "/home/kc/blancexchangeapi/core_app_root/user_services/bankmanagement/routers.py", line 2, in <module>
    from core_app_root.user_services.bankmanagement.viewsets.bankmanagementviewset import BankManagementViewset,UserBankDetailsViewset
  File "/home/kc/blancexchangeapi/core_app_root/user_services/bankmanagement/viewsets/bankmanagementviewset.py", line 80
    return Response({"status":False,"message":"bank name fetched successfully")
                                                                              ^
SyntaxError: closing parenthesis ')' does not match opening parenthesis '{'
Performing system checks...

Exception in thread django-main-thread:
Traceback (most recent call last):
  File "/root/anaconda3/lib/python3.10/threading.py", line 1016, in _bootstrap_inner
    self.run()
  File "/root/anaconda3/lib/python3.10/threading.py", line 953, in run
    self._target(*self._args, **self._kwargs)
  File "/root/anaconda3/lib/python3.10/site-packages/django/utils/autoreload.py", line 64, in wrapper
    fn(*args, **kwargs)
  File "/root/anaconda3/lib/python3.10/site-packages/django/core/management/commands/runserver.py", line 133, in inner_run
    self.check(display_num_errors=True)
  File "/root/anaconda3/lib/python3.10/site-packages/django/core/management/base.py", line 485, in check
    all_issues = checks.run_checks(
  File "/root/anaconda3/lib/python3.10/site-packages/django/core/checks/registry.py", line 88, in run_checks
    new_errors = check(app_configs=app_configs, databases=databases)
  File "/root/anaconda3/lib/python3.10/site-packages/django/core/checks/urls.py", line 14, in check_url_config
    return check_resolver(resolver)
  File "/root/anaconda3/lib/python3.10/site-packages/django/core/checks/urls.py", line 24, in check_resolver
    return check_method()
  File "/root/anaconda3/lib/python3.10/site-packages/django/urls/resolvers.py", line 494, in check
    for pattern in self.url_patterns:
  File "/root/anaconda3/lib/python3.10/site-packages/django/utils/functional.py", line 57, in __get__
    res = instance.__dict__[self.name] = self.func(instance)
  File "/root/anaconda3/lib/python3.10/site-packages/django/urls/resolvers.py", line 715, in url_patterns
    patterns = getattr(self.urlconf_module, "urlpatterns", self.urlconf_module)
  File "/root/anaconda3/lib/python3.10/site-packages/django/utils/functional.py", line 57, in __get__
    res = instance.__dict__[self.name] = self.func(instance)
  File "/root/anaconda3/lib/python3.10/site-packages/django/urls/resolvers.py", line 708, in urlconf_module
    return import_module(self.urlconf_name)
  File "/root/anaconda3/lib/python3.10/importlib/__init__.py", line 126, in import_module
    return _bootstrap._gcd_import(name[level:], package, level)
  File "<frozen importlib._bootstrap>", line 1050, in _gcd_import
  File "<frozen importlib._bootstrap>", line 1027, in _find_and_load
  File "<frozen importlib._bootstrap>", line 1006, in _find_and_load_unlocked
  File "<frozen importlib._bootstrap>", line 688, in _load_unlocked
  File "<frozen importlib._bootstrap_external>", line 883, in exec_module
  File "<frozen importlib._bootstrap>", line 241, in _call_with_frames_removed
  File "/home/kc/blancexchangeapi/blankexchange/urls.py", line 45, in <module>
    path('bank/',include(('core_app_root.user_services.bankmanagement.routers','core_app_root.user_services.bankmanagement'))),
  File "/root/anaconda3/lib/python3.10/site-packages/django/urls/conf.py", line 38, in include
    urlconf_module = import_module(urlconf_module)
  File "/root/anaconda3/lib/python3.10/importlib/__init__.py", line 126, in import_module
    return _bootstrap._gcd_import(name[level:], package, level)
  File "<frozen importlib._bootstrap>", line 1050, in _gcd_import
  File "<frozen importlib._bootstrap>", line 1027, in _find_and_load
  File "<frozen importlib._bootstrap>", line 1006, in _find_and_load_unlocked
  File "<frozen importlib._bootstrap>", line 688, in _load_unlocked
  File "<frozen importlib._bootstrap_external>", line 883, in exec_module
  File "<frozen importlib._bootstrap>", line 241, in _call_with_frames_removed
  File "/home/kc/blancexchangeapi/core_app_root/user_services/bankmanagement/routers.py", line 2, in <module>
    from core_app_root.user_services.bankmanagement.viewsets.bankmanagementviewset import BankManagementViewset,UserBankDetailsViewset
  File "/home/kc/blancexchangeapi/core_app_root/user_services/bankmanagement/viewsets/bankmanagementviewset.py", line 80
    return Response({"status":False,"message":"bank name fetched successfully")
                                                                              ^
SyntaxError: closing parenthesis ')' does not match opening parenthesis '{'
Performing system checks...

System check identified no issues (0 silenced).
June 17, 2024 - 01:33:03
Django version 4.2.11, using settings 'blankexchange.settings'
Starting development server at http://192.81.210.127:1234/
Quit the server with CONTROL-C.

Performing system checks...

System check identified no issues (0 silenced).
June 17, 2024 - 01:38:56
Django version 4.2.11, using settings 'blankexchange.settings'
Starting development server at http://192.81.210.127:1234/
Quit the server with CONTROL-C.

Performing system checks...

Exception in thread django-main-thread:
Traceback (most recent call last):
  File "/root/anaconda3/lib/python3.10/threading.py", line 1016, in _bootstrap_inner
    self.run()
  File "/root/anaconda3/lib/python3.10/threading.py", line 953, in run
    self._target(*self._args, **self._kwargs)
  File "/root/anaconda3/lib/python3.10/site-packages/django/utils/autoreload.py", line 64, in wrapper
    fn(*args, **kwargs)
  File "/root/anaconda3/lib/python3.10/site-packages/django/core/management/commands/runserver.py", line 133, in inner_run
    self.check(display_num_errors=True)
  File "/root/anaconda3/lib/python3.10/site-packages/django/core/management/base.py", line 485, in check
    all_issues = checks.run_checks(
  File "/root/anaconda3/lib/python3.10/site-packages/django/core/checks/registry.py", line 88, in run_checks
    new_errors = check(app_configs=app_configs, databases=databases)
  File "/root/anaconda3/lib/python3.10/site-packages/django/core/checks/urls.py", line 14, in check_url_config
    return check_resolver(resolver)
  File "/root/anaconda3/lib/python3.10/site-packages/django/core/checks/urls.py", line 24, in check_resolver
    return check_method()
  File "/root/anaconda3/lib/python3.10/site-packages/django/urls/resolvers.py", line 494, in check
    for pattern in self.url_patterns:
  File "/root/anaconda3/lib/python3.10/site-packages/django/utils/functional.py", line 57, in __get__
    res = instance.__dict__[self.name] = self.func(instance)
  File "/root/anaconda3/lib/python3.10/site-packages/django/urls/resolvers.py", line 715, in url_patterns
    patterns = getattr(self.urlconf_module, "urlpatterns", self.urlconf_module)
  File "/root/anaconda3/lib/python3.10/site-packages/django/utils/functional.py", line 57, in __get__
    res = instance.__dict__[self.name] = self.func(instance)
  File "/root/anaconda3/lib/python3.10/site-packages/django/urls/resolvers.py", line 708, in urlconf_module
    return import_module(self.urlconf_name)
  File "/root/anaconda3/lib/python3.10/importlib/__init__.py", line 126, in import_module
    return _bootstrap._gcd_import(name[level:], package, level)
  File "<frozen importlib._bootstrap>", line 1050, in _gcd_import
  File "<frozen importlib._bootstrap>", line 1027, in _find_and_load
  File "<frozen importlib._bootstrap>", line 1006, in _find_and_load_unlocked
  File "<frozen importlib._bootstrap>", line 688, in _load_unlocked
  File "<frozen importlib._bootstrap_external>", line 883, in exec_module
  File "<frozen importlib._bootstrap>", line 241, in _call_with_frames_removed
  File "/home/kc/blancexchangeapi/blankexchange/urls.py", line 45, in <module>
    path('bank/',include(('core_app_root.user_services.bankmanagement.routers','core_app_root.user_services.bankmanagement'))),
  File "/root/anaconda3/lib/python3.10/site-packages/django/urls/conf.py", line 38, in include
    urlconf_module = import_module(urlconf_module)
  File "/root/anaconda3/lib/python3.10/importlib/__init__.py", line 126, in import_module
    return _bootstrap._gcd_import(name[level:], package, level)
  File "<frozen importlib._bootstrap>", line 1050, in _gcd_import
  File "<frozen importlib._bootstrap>", line 1027, in _find_and_load
  File "<frozen importlib._bootstrap>", line 1006, in _find_and_load_unlocked
  File "<frozen importlib._bootstrap>", line 688, in _load_unlocked
  File "<frozen importlib._bootstrap_external>", line 883, in exec_module
  File "<frozen importlib._bootstrap>", line 241, in _call_with_frames_removed
  File "/home/kc/blancexchangeapi/core_app_root/user_services/bankmanagement/routers.py", line 2, in <module>
    from core_app_root.user_services.bankmanagement.viewsets.bankmanagementviewset import BankManagementViewset,UserBankDetailsViewset
  File "/home/kc/blancexchangeapi/core_app_root/user_services/bankmanagement/viewsets/bankmanagementviewset.py", line 80
    return Response({"status":False,"message":"bank name fetched successfully"})
IndentationError: unexpected indent
Performing system checks...

System check identified no issues (0 silenced).
June 17, 2024 - 01:42:11
Django version 4.2.11, using settings 'blankexchange.settings'
Starting development server at http://192.81.210.127:1234/
Quit the server with CONTROL-C.

Performing system checks...

Exception in thread django-main-thread:
Traceback (most recent call last):
  File "/root/anaconda3/lib/python3.10/threading.py", line 1016, in _bootstrap_inner
    self.run()
  File "/root/anaconda3/lib/python3.10/threading.py", line 953, in run
    self._target(*self._args, **self._kwargs)
  File "/root/anaconda3/lib/python3.10/site-packages/django/utils/autoreload.py", line 64, in wrapper
    fn(*args, **kwargs)
  File "/root/anaconda3/lib/python3.10/site-packages/django/core/management/commands/runserver.py", line 133, in inner_run
    self.check(display_num_errors=True)
  File "/root/anaconda3/lib/python3.10/site-packages/django/core/management/base.py", line 485, in check
    all_issues = checks.run_checks(
  File "/root/anaconda3/lib/python3.10/site-packages/django/core/checks/registry.py", line 88, in run_checks
    new_errors = check(app_configs=app_configs, databases=databases)
  File "/root/anaconda3/lib/python3.10/site-packages/django/core/checks/urls.py", line 14, in check_url_config
    return check_resolver(resolver)
  File "/root/anaconda3/lib/python3.10/site-packages/django/core/checks/urls.py", line 24, in check_resolver
    return check_method()
  File "/root/anaconda3/lib/python3.10/site-packages/django/urls/resolvers.py", line 494, in check
    for pattern in self.url_patterns:
  File "/root/anaconda3/lib/python3.10/site-packages/django/utils/functional.py", line 57, in __get__
    res = instance.__dict__[self.name] = self.func(instance)
  File "/root/anaconda3/lib/python3.10/site-packages/django/urls/resolvers.py", line 715, in url_patterns
    patterns = getattr(self.urlconf_module, "urlpatterns", self.urlconf_module)
  File "/root/anaconda3/lib/python3.10/site-packages/django/utils/functional.py", line 57, in __get__
    res = instance.__dict__[self.name] = self.func(instance)
  File "/root/anaconda3/lib/python3.10/site-packages/django/urls/resolvers.py", line 708, in urlconf_module
    return import_module(self.urlconf_name)
  File "/root/anaconda3/lib/python3.10/importlib/__init__.py", line 126, in import_module
    return _bootstrap._gcd_import(name[level:], package, level)
  File "<frozen importlib._bootstrap>", line 1050, in _gcd_import
  File "<frozen importlib._bootstrap>", line 1027, in _find_and_load
  File "<frozen importlib._bootstrap>", line 1006, in _find_and_load_unlocked
  File "<frozen importlib._bootstrap>", line 688, in _load_unlocked
  File "<frozen importlib._bootstrap_external>", line 883, in exec_module
  File "<frozen importlib._bootstrap>", line 241, in _call_with_frames_removed
  File "/home/kc/blancexchangeapi/blankexchange/urls.py", line 45, in <module>
    path('bank/',include(('core_app_root.user_services.bankmanagement.routers','core_app_root.user_services.bankmanagement'))),
  File "/root/anaconda3/lib/python3.10/site-packages/django/urls/conf.py", line 38, in include
    urlconf_module = import_module(urlconf_module)
  File "/root/anaconda3/lib/python3.10/importlib/__init__.py", line 126, in import_module
    return _bootstrap._gcd_import(name[level:], package, level)
  File "<frozen importlib._bootstrap>", line 1050, in _gcd_import
  File "<frozen importlib._bootstrap>", line 1027, in _find_and_load
  File "<frozen importlib._bootstrap>", line 1006, in _find_and_load_unlocked
  File "<frozen importlib._bootstrap>", line 688, in _load_unlocked
  File "<frozen importlib._bootstrap_external>", line 883, in exec_module
  File "<frozen importlib._bootstrap>", line 241, in _call_with_frames_removed
  File "/home/kc/blancexchangeapi/core_app_root/user_services/bankmanagement/routers.py", line 2, in <module>
    from core_app_root.user_services.bankmanagement.viewsets.bankmanagementviewset import BankManagementViewset,UserBankDetailsViewset
  File "/home/kc/blancexchangeapi/core_app_root/user_services/bankmanagement/viewsets/bankmanagementviewset.py", line 29, in <module>
    class UserBankDetailsViewset(viewsets.ModelViewSet):
  File "/home/kc/blancexchangeapi/core_app_root/user_services/bankmanagement/viewsets/bankmanagementviewset.py", line 35, in UserBankDetailsViewset
    @action(detail=False, methods=['post'])
NameError: name 'action' is not defined
Performing system checks...

Exception in thread django-main-thread:
Traceback (most recent call last):
  File "/root/anaconda3/lib/python3.10/threading.py", line 1016, in _bootstrap_inner
    self.run()
  File "/root/anaconda3/lib/python3.10/threading.py", line 953, in run
    self._target(*self._args, **self._kwargs)
  File "/root/anaconda3/lib/python3.10/site-packages/django/utils/autoreload.py", line 64, in wrapper
    fn(*args, **kwargs)
  File "/root/anaconda3/lib/python3.10/site-packages/django/core/management/commands/runserver.py", line 133, in inner_run
    self.check(display_num_errors=True)
  File "/root/anaconda3/lib/python3.10/site-packages/django/core/management/base.py", line 485, in check
    all_issues = checks.run_checks(
  File "/root/anaconda3/lib/python3.10/site-packages/django/core/checks/registry.py", line 88, in run_checks
    new_errors = check(app_configs=app_configs, databases=databases)
  File "/root/anaconda3/lib/python3.10/site-packages/django/core/checks/urls.py", line 14, in check_url_config
    return check_resolver(resolver)
  File "/root/anaconda3/lib/python3.10/site-packages/django/core/checks/urls.py", line 24, in check_resolver
    return check_method()
  File "/root/anaconda3/lib/python3.10/site-packages/django/urls/resolvers.py", line 494, in check
    for pattern in self.url_patterns:
  File "/root/anaconda3/lib/python3.10/site-packages/django/utils/functional.py", line 57, in __get__
    res = instance.__dict__[self.name] = self.func(instance)
  File "/root/anaconda3/lib/python3.10/site-packages/django/urls/resolvers.py", line 715, in url_patterns
    patterns = getattr(self.urlconf_module, "urlpatterns", self.urlconf_module)
  File "/root/anaconda3/lib/python3.10/site-packages/django/utils/functional.py", line 57, in __get__
    res = instance.__dict__[self.name] = self.func(instance)
  File "/root/anaconda3/lib/python3.10/site-packages/django/urls/resolvers.py", line 708, in urlconf_module
    return import_module(self.urlconf_name)
  File "/root/anaconda3/lib/python3.10/importlib/__init__.py", line 126, in import_module
    return _bootstrap._gcd_import(name[level:], package, level)
  File "<frozen importlib._bootstrap>", line 1050, in _gcd_import
  File "<frozen importlib._bootstrap>", line 1027, in _find_and_load
  File "<frozen importlib._bootstrap>", line 1006, in _find_and_load_unlocked
  File "<frozen importlib._bootstrap>", line 688, in _load_unlocked
  File "<frozen importlib._bootstrap_external>", line 883, in exec_module
  File "<frozen importlib._bootstrap>", line 241, in _call_with_frames_removed
  File "/home/kc/blancexchangeapi/blankexchange/urls.py", line 45, in <module>
    path('bank/',include(('core_app_root.user_services.bankmanagement.routers','core_app_root.user_services.bankmanagement'))),
  File "/root/anaconda3/lib/python3.10/site-packages/django/urls/conf.py", line 38, in include
    urlconf_module = import_module(urlconf_module)
  File "/root/anaconda3/lib/python3.10/importlib/__init__.py", line 126, in import_module
    return _bootstrap._gcd_import(name[level:], package, level)
  File "<frozen importlib._bootstrap>", line 1050, in _gcd_import
  File "<frozen importlib._bootstrap>", line 1027, in _find_and_load
  File "<frozen importlib._bootstrap>", line 1006, in _find_and_load_unlocked
  File "<frozen importlib._bootstrap>", line 688, in _load_unlocked
  File "<frozen importlib._bootstrap_external>", line 883, in exec_module
  File "<frozen importlib._bootstrap>", line 241, in _call_with_frames_removed
  File "/home/kc/blancexchangeapi/core_app_root/user_services/bankmanagement/routers.py", line 2, in <module>
    from core_app_root.user_services.bankmanagement.viewsets.bankmanagementviewset import BankManagementViewset,UserBankDetailsViewset
  File "/home/kc/blancexchangeapi/core_app_root/user_services/bankmanagement/viewsets/bankmanagementviewset.py", line 12, in <module>
    import aiohttp
ModuleNotFoundError: No module named 'aiohttp'
Performing system checks...

System check identified no issues (0 silenced).
June 17, 2024 - 01:45:01
Django version 4.2.11, using settings 'blankexchange.settings'
Starting development server at http://192.81.210.127:1234/
Quit the server with CONTROL-C.

Performing system checks...

Exception in thread django-main-thread:
Traceback (most recent call last):
  File "/root/anaconda3/lib/python3.10/threading.py", line 1016, in _bootstrap_inner
    self.run()
  File "/root/anaconda3/lib/python3.10/threading.py", line 953, in run
    self._target(*self._args, **self._kwargs)
  File "/root/anaconda3/lib/python3.10/site-packages/django/utils/autoreload.py", line 64, in wrapper
    fn(*args, **kwargs)
  File "/root/anaconda3/lib/python3.10/site-packages/django/core/management/commands/runserver.py", line 133, in inner_run
    self.check(display_num_errors=True)
  File "/root/anaconda3/lib/python3.10/site-packages/django/core/management/base.py", line 485, in check
    all_issues = checks.run_checks(
  File "/root/anaconda3/lib/python3.10/site-packages/django/core/checks/registry.py", line 88, in run_checks
    new_errors = check(app_configs=app_configs, databases=databases)
  File "/root/anaconda3/lib/python3.10/site-packages/django/core/checks/urls.py", line 14, in check_url_config
    return check_resolver(resolver)
  File "/root/anaconda3/lib/python3.10/site-packages/django/core/checks/urls.py", line 24, in check_resolver
    return check_method()
  File "/root/anaconda3/lib/python3.10/site-packages/django/urls/resolvers.py", line 494, in check
    for pattern in self.url_patterns:
  File "/root/anaconda3/lib/python3.10/site-packages/django/utils/functional.py", line 57, in __get__
    res = instance.__dict__[self.name] = self.func(instance)
  File "/root/anaconda3/lib/python3.10/site-packages/django/urls/resolvers.py", line 715, in url_patterns
    patterns = getattr(self.urlconf_module, "urlpatterns", self.urlconf_module)
  File "/root/anaconda3/lib/python3.10/site-packages/django/utils/functional.py", line 57, in __get__
    res = instance.__dict__[self.name] = self.func(instance)
  File "/root/anaconda3/lib/python3.10/site-packages/django/urls/resolvers.py", line 708, in urlconf_module
    return import_module(self.urlconf_name)
  File "/root/anaconda3/lib/python3.10/importlib/__init__.py", line 126, in import_module
    return _bootstrap._gcd_import(name[level:], package, level)
  File "<frozen importlib._bootstrap>", line 1050, in _gcd_import
  File "<frozen importlib._bootstrap>", line 1027, in _find_and_load
  File "<frozen importlib._bootstrap>", line 1006, in _find_and_load_unlocked
  File "<frozen importlib._bootstrap>", line 688, in _load_unlocked
  File "<frozen importlib._bootstrap_external>", line 883, in exec_module
  File "<frozen importlib._bootstrap>", line 241, in _call_with_frames_removed
  File "/home/kc/blancexchangeapi/blankexchange/urls.py", line 45, in <module>
    path('bank/',include(('core_app_root.user_services.bankmanagement.routers','core_app_root.user_services.bankmanagement'))),
  File "/root/anaconda3/lib/python3.10/site-packages/django/urls/conf.py", line 38, in include
    urlconf_module = import_module(urlconf_module)
  File "/root/anaconda3/lib/python3.10/importlib/__init__.py", line 126, in import_module
    return _bootstrap._gcd_import(name[level:], package, level)
  File "<frozen importlib._bootstrap>", line 1050, in _gcd_import
  File "<frozen importlib._bootstrap>", line 1027, in _find_and_load
  File "<frozen importlib._bootstrap>", line 1006, in _find_and_load_unlocked
  File "<frozen importlib._bootstrap>", line 688, in _load_unlocked
  File "<frozen importlib._bootstrap_external>", line 883, in exec_module
  File "<frozen importlib._bootstrap>", line 241, in _call_with_frames_removed
  File "/home/kc/blancexchangeapi/core_app_root/user_services/bankmanagement/routers.py", line 9, in <module>
    *router.urls
  File "/root/anaconda3/lib/python3.10/site-packages/rest_framework/routers.py", line 89, in urls
    self._urls = self.get_urls()
  File "/root/anaconda3/lib/python3.10/site-packages/rest_framework/routers.py", line 274, in get_urls
    routes = self.get_routes(viewset)
  File "/root/anaconda3/lib/python3.10/site-packages/rest_framework/routers.py", line 195, in get_routes
    raise ImproperlyConfigured(msg % ', '.join(not_allowed))
django.core.exceptions.ImproperlyConfigured: Cannot use the @action decorator on the following methods, as they are existing routes: create
Performing system checks...

Exception in thread django-main-thread:
Traceback (most recent call last):
  File "/root/anaconda3/lib/python3.10/threading.py", line 1016, in _bootstrap_inner
    self.run()
  File "/root/anaconda3/lib/python3.10/threading.py", line 953, in run
    self._target(*self._args, **self._kwargs)
  File "/root/anaconda3/lib/python3.10/site-packages/django/utils/autoreload.py", line 64, in wrapper
    fn(*args, **kwargs)
  File "/root/anaconda3/lib/python3.10/site-packages/django/core/management/commands/runserver.py", line 133, in inner_run
    self.check(display_num_errors=True)
  File "/root/anaconda3/lib/python3.10/site-packages/django/core/management/base.py", line 485, in check
    all_issues = checks.run_checks(
  File "/root/anaconda3/lib/python3.10/site-packages/django/core/checks/registry.py", line 88, in run_checks
    new_errors = check(app_configs=app_configs, databases=databases)
  File "/root/anaconda3/lib/python3.10/site-packages/django/core/checks/urls.py", line 14, in check_url_config
    return check_resolver(resolver)
  File "/root/anaconda3/lib/python3.10/site-packages/django/core/checks/urls.py", line 24, in check_resolver
    return check_method()
  File "/root/anaconda3/lib/python3.10/site-packages/django/urls/resolvers.py", line 494, in check
    for pattern in self.url_patterns:
  File "/root/anaconda3/lib/python3.10/site-packages/django/utils/functional.py", line 57, in __get__
    res = instance.__dict__[self.name] = self.func(instance)
  File "/root/anaconda3/lib/python3.10/site-packages/django/urls/resolvers.py", line 715, in url_patterns
    patterns = getattr(self.urlconf_module, "urlpatterns", self.urlconf_module)
  File "/root/anaconda3/lib/python3.10/site-packages/django/utils/functional.py", line 57, in __get__
    res = instance.__dict__[self.name] = self.func(instance)
  File "/root/anaconda3/lib/python3.10/site-packages/django/urls/resolvers.py", line 708, in urlconf_module
    return import_module(self.urlconf_name)
  File "/root/anaconda3/lib/python3.10/importlib/__init__.py", line 126, in import_module
    return _bootstrap._gcd_import(name[level:], package, level)
  File "<frozen importlib._bootstrap>", line 1050, in _gcd_import
  File "<frozen importlib._bootstrap>", line 1027, in _find_and_load
  File "<frozen importlib._bootstrap>", line 1006, in _find_and_load_unlocked
  File "<frozen importlib._bootstrap>", line 688, in _load_unlocked
  File "<frozen importlib._bootstrap_external>", line 883, in exec_module
  File "<frozen importlib._bootstrap>", line 241, in _call_with_frames_removed
  File "/home/kc/blancexchangeapi/blankexchange/urls.py", line 45, in <module>
    path('bank/',include(('core_app_root.user_services.bankmanagement.routers','core_app_root.user_services.bankmanagement'))),
  File "/root/anaconda3/lib/python3.10/site-packages/django/urls/conf.py", line 38, in include
    urlconf_module = import_module(urlconf_module)
  File "/root/anaconda3/lib/python3.10/importlib/__init__.py", line 126, in import_module
    return _bootstrap._gcd_import(name[level:], package, level)
  File "<frozen importlib._bootstrap>", line 1050, in _gcd_import
  File "<frozen importlib._bootstrap>", line 1027, in _find_and_load
  File "<frozen importlib._bootstrap>", line 1006, in _find_and_load_unlocked
  File "<frozen importlib._bootstrap>", line 688, in _load_unlocked
  File "<frozen importlib._bootstrap_external>", line 883, in exec_module
  File "<frozen importlib._bootstrap>", line 241, in _call_with_frames_removed
  File "/home/kc/blancexchangeapi/core_app_root/user_services/bankmanagement/routers.py", line 9, in <module>
    *router.urls
  File "/root/anaconda3/lib/python3.10/site-packages/rest_framework/routers.py", line 89, in urls
    self._urls = self.get_urls()
  File "/root/anaconda3/lib/python3.10/site-packages/rest_framework/routers.py", line 274, in get_urls
    routes = self.get_routes(viewset)
  File "/root/anaconda3/lib/python3.10/site-packages/rest_framework/routers.py", line 195, in get_routes
    raise ImproperlyConfigured(msg % ', '.join(not_allowed))
django.core.exceptions.ImproperlyConfigured: Cannot use the @action decorator on the following methods, as they are existing routes: create
Performing system checks...

Exception in thread django-main-thread:
Traceback (most recent call last):
  File "/root/anaconda3/lib/python3.10/threading.py", line 1016, in _bootstrap_inner
    self.run()
  File "/root/anaconda3/lib/python3.10/threading.py", line 953, in run
    self._target(*self._args, **self._kwargs)
  File "/root/anaconda3/lib/python3.10/site-packages/django/utils/autoreload.py", line 64, in wrapper
    fn(*args, **kwargs)
  File "/root/anaconda3/lib/python3.10/site-packages/django/core/management/commands/runserver.py", line 133, in inner_run
    self.check(display_num_errors=True)
  File "/root/anaconda3/lib/python3.10/site-packages/django/core/management/base.py", line 485, in check
    all_issues = checks.run_checks(
  File "/root/anaconda3/lib/python3.10/site-packages/django/core/checks/registry.py", line 88, in run_checks
    new_errors = check(app_configs=app_configs, databases=databases)
  File "/root/anaconda3/lib/python3.10/site-packages/django/core/checks/urls.py", line 14, in check_url_config
    return check_resolver(resolver)
  File "/root/anaconda3/lib/python3.10/site-packages/django/core/checks/urls.py", line 24, in check_resolver
    return check_method()
  File "/root/anaconda3/lib/python3.10/site-packages/django/urls/resolvers.py", line 494, in check
    for pattern in self.url_patterns:
  File "/root/anaconda3/lib/python3.10/site-packages/django/utils/functional.py", line 57, in __get__
    res = instance.__dict__[self.name] = self.func(instance)
  File "/root/anaconda3/lib/python3.10/site-packages/django/urls/resolvers.py", line 715, in url_patterns
    patterns = getattr(self.urlconf_module, "urlpatterns", self.urlconf_module)
  File "/root/anaconda3/lib/python3.10/site-packages/django/utils/functional.py", line 57, in __get__
    res = instance.__dict__[self.name] = self.func(instance)
  File "/root/anaconda3/lib/python3.10/site-packages/django/urls/resolvers.py", line 708, in urlconf_module
    return import_module(self.urlconf_name)
  File "/root/anaconda3/lib/python3.10/importlib/__init__.py", line 126, in import_module
    return _bootstrap._gcd_import(name[level:], package, level)
  File "<frozen importlib._bootstrap>", line 1050, in _gcd_import
  File "<frozen importlib._bootstrap>", line 1027, in _find_and_load
  File "<frozen importlib._bootstrap>", line 1006, in _find_and_load_unlocked
  File "<frozen importlib._bootstrap>", line 688, in _load_unlocked
  File "<frozen importlib._bootstrap_external>", line 883, in exec_module
  File "<frozen importlib._bootstrap>", line 241, in _call_with_frames_removed
  File "/home/kc/blancexchangeapi/blankexchange/urls.py", line 45, in <module>
    path('bank/',include(('core_app_root.user_services.bankmanagement.routers','core_app_root.user_services.bankmanagement'))),
  File "/root/anaconda3/lib/python3.10/site-packages/django/urls/conf.py", line 38, in include
    urlconf_module = import_module(urlconf_module)
  File "/root/anaconda3/lib/python3.10/importlib/__init__.py", line 126, in import_module
    return _bootstrap._gcd_import(name[level:], package, level)
  File "<frozen importlib._bootstrap>", line 1050, in _gcd_import
  File "<frozen importlib._bootstrap>", line 1027, in _find_and_load
  File "<frozen importlib._bootstrap>", line 1006, in _find_and_load_unlocked
  File "<frozen importlib._bootstrap>", line 688, in _load_unlocked
  File "<frozen importlib._bootstrap_external>", line 883, in exec_module
  File "<frozen importlib._bootstrap>", line 241, in _call_with_frames_removed
  File "/home/kc/blancexchangeapi/core_app_root/user_services/bankmanagement/routers.py", line 9, in <module>
    *router.urls
  File "/root/anaconda3/lib/python3.10/site-packages/rest_framework/routers.py", line 89, in urls
    self._urls = self.get_urls()
  File "/root/anaconda3/lib/python3.10/site-packages/rest_framework/routers.py", line 274, in get_urls
    routes = self.get_routes(viewset)
  File "/root/anaconda3/lib/python3.10/site-packages/rest_framework/routers.py", line 195, in get_routes
    raise ImproperlyConfigured(msg % ', '.join(not_allowed))
django.core.exceptions.ImproperlyConfigured: Cannot use the @action decorator on the following methods, as they are existing routes: create
Performing system checks...

System check identified no issues (0 silenced).
June 17, 2024 - 01:48:42
Django version 4.2.11, using settings 'blankexchange.settings'
Starting development server at http://192.81.210.127:1234/
Quit the server with CONTROL-C.

Performing system checks...

Exception in thread django-main-thread:
Traceback (most recent call last):
  File "/root/anaconda3/lib/python3.10/threading.py", line 1016, in _bootstrap_inner
    self.run()
  File "/root/anaconda3/lib/python3.10/threading.py", line 953, in run
    self._target(*self._args, **self._kwargs)
  File "/root/anaconda3/lib/python3.10/site-packages/django/utils/autoreload.py", line 64, in wrapper
    fn(*args, **kwargs)
  File "/root/anaconda3/lib/python3.10/site-packages/django/core/management/commands/runserver.py", line 133, in inner_run
    self.check(display_num_errors=True)
  File "/root/anaconda3/lib/python3.10/site-packages/django/core/management/base.py", line 485, in check
    all_issues = checks.run_checks(
  File "/root/anaconda3/lib/python3.10/site-packages/django/core/checks/registry.py", line 88, in run_checks
    new_errors = check(app_configs=app_configs, databases=databases)
  File "/root/anaconda3/lib/python3.10/site-packages/django/core/checks/urls.py", line 14, in check_url_config
    return check_resolver(resolver)
  File "/root/anaconda3/lib/python3.10/site-packages/django/core/checks/urls.py", line 24, in check_resolver
    return check_method()
  File "/root/anaconda3/lib/python3.10/site-packages/django/urls/resolvers.py", line 494, in check
    for pattern in self.url_patterns:
  File "/root/anaconda3/lib/python3.10/site-packages/django/utils/functional.py", line 57, in __get__
    res = instance.__dict__[self.name] = self.func(instance)
  File "/root/anaconda3/lib/python3.10/site-packages/django/urls/resolvers.py", line 715, in url_patterns
    patterns = getattr(self.urlconf_module, "urlpatterns", self.urlconf_module)
  File "/root/anaconda3/lib/python3.10/site-packages/django/utils/functional.py", line 57, in __get__
    res = instance.__dict__[self.name] = self.func(instance)
  File "/root/anaconda3/lib/python3.10/site-packages/django/urls/resolvers.py", line 708, in urlconf_module
    return import_module(self.urlconf_name)
  File "/root/anaconda3/lib/python3.10/importlib/__init__.py", line 126, in import_module
    return _bootstrap._gcd_import(name[level:], package, level)
  File "<frozen importlib._bootstrap>", line 1050, in _gcd_import
  File "<frozen importlib._bootstrap>", line 1027, in _find_and_load
  File "<frozen importlib._bootstrap>", line 1006, in _find_and_load_unlocked
  File "<frozen importlib._bootstrap>", line 688, in _load_unlocked
  File "<frozen importlib._bootstrap_external>", line 883, in exec_module
  File "<frozen importlib._bootstrap>", line 241, in _call_with_frames_removed
  File "/home/kc/blancexchangeapi/blankexchange/urls.py", line 45, in <module>
    path('bank/',include(('core_app_root.user_services.bankmanagement.routers','core_app_root.user_services.bankmanagement'))),
  File "/root/anaconda3/lib/python3.10/site-packages/django/urls/conf.py", line 38, in include
    urlconf_module = import_module(urlconf_module)
  File "/root/anaconda3/lib/python3.10/importlib/__init__.py", line 126, in import_module
    return _bootstrap._gcd_import(name[level:], package, level)
  File "<frozen importlib._bootstrap>", line 1050, in _gcd_import
  File "<frozen importlib._bootstrap>", line 1027, in _find_and_load
  File "<frozen importlib._bootstrap>", line 1006, in _find_and_load_unlocked
  File "<frozen importlib._bootstrap>", line 688, in _load_unlocked
  File "<frozen importlib._bootstrap_external>", line 883, in exec_module
  File "<frozen importlib._bootstrap>", line 241, in _call_with_frames_removed
  File "/home/kc/blancexchangeapi/core_app_root/user_services/bankmanagement/routers.py", line 2, in <module>
    from core_app_root.user_services.bankmanagement.viewsets.bankmanagementviewset import BankManagementViewset,UserBankDetailsViewset
  File "/home/kc/blancexchangeapi/core_app_root/user_services/bankmanagement/viewsets/bankmanagementviewset.py", line 80
    return Response({"status":False,"message":"bank name fetched successfully")
                                                                              ^
SyntaxError: closing parenthesis ')' does not match opening parenthesis '{'
Performing system checks...

System check identified no issues (0 silenced).
June 17, 2024 - 01:48:50
Django version 4.2.11, using settings 'blankexchange.settings'
Starting development server at http://192.81.210.127:1234/
Quit the server with CONTROL-C.

